Workbook

Sheet 인사현황
A1: =TODAY() -> 46113 | D1: 기본이력사항 | P1: 회사 근무 현황 | AK1: 급여정보 | AO1: 기타 인사 관련 참고 사항
A3: 이름 | B3: 소속 본부 | C3: 소속팀 | D3: 나이(만) | E3: 병역 | F3: 결혼유무 | G3: 자녀 | H3: 개인이력 | I3: 주소 | J3: 학력 | K3: 최종학교명 | L3: 주전공 | M3: 급여계좌(우리) | N3: 근무년수 | O3: 근무일수 | P3: 입사년도 | Q3: 입사년 | R3: 입사월 | S3: 입사일 | T3: 재직여부 | U3: 퇴사년도 | V3: 퇴사년 | W3: 퇴사월 | X3: 퇴사일 | Y3: 퇴직사유 | Z3: 정규직 전환일 | AA3: 최초 직위 | AB3: 대리 승진일 | AC3: 과장 승진일 | AD3: 차장 승진일 | AE3: 부장 승진일 | AF3: 수석부장 승진일 | AG3: 현 승급 | AH3: 포상여부 | AI3: 휴직기간 | AJ3: 최종 직급 | AK3: 월급여 | AL3: 인센티브 | AM3: 기준연봉 | AN3: 실제연봉
A4: 조경희 | B4: 연구소 | D4: =조경희!N6 -> 61 | F4: 유 | G4: 2 | I4: 서울특별시 동작구 동작대로29길 109동1103호 사당동 극동아파트 | J4: =조경희!Q19 -> 대졸 | K4: =조경희!I19 -> 서울대학교 | L4: =조경희!L19 -> 계산통계학 | M4: 1002-137-499461 | N4: =O4/365 -> 25.59726 | O4: =$A$1-P4 -> 9343 | P4: =조경희!E3 -> 36770 | Q4: =YEAR(P4) -> 2000 | R4: =MONTH(P4) -> 9 | S4: =DAY(P4) -> 1 | T4: 재직 | AA4: 소장 | AG4: 41640 | AJ4: 전무이사
A5: 김우찬 | B5: =김우찬!AA3 -> 학원사업본부 | D5: =김우찬!N6 -> 49 | E5: 필 | F5: 유 | G5: 3 | I5: =김우찬!E8 -> 서울시 영등포구 | J5: =김우찬!Q19 -> 대졸 | K5: =김우찬!I20 -> 숭실대학교 | L5: =김우찬!L20 -> 전산원 | M5: 461-116613-02-101 | N5: =O5/365 -> 24.178082 | O5: =$A$1-P5 -> 8825 | P5: =김우찬!E3 -> 37288 | Q5: =YEAR(P5) -> 2002 | R5: =MONTH(P5) -> 2 | S5: =DAY(P5) -> 1 | T5: 재직 | Z5: 37438 | AA5: 사원 | AB5: 38100 | AC5: 38749 | AD5: 39814 | AE5: 41275 | AJ5: 본부장
A6: 강종태 | B6: =강종태!AA3 -> 경영총괄실 | D6: =강종태!N6 -> 50 | E6: 필 | F6: 유 | G6: 1 | I6: =강종태!E8 -> 경기도 의왕시 | J6: =강종태!Q19 -> 대졸 | K6: =강종태!I20 -> 서울대 | L6: =강종태!L20 -> 기계항공공학부 | M6: 1002-833-449249 | N6: =O6/365 -> 22.59726 | O6: =$A$1-P6 -> 8248 | P6: =강종태!E3 -> 37865 | Q6: =YEAR(P6) -> 2003 | R6: =MONTH(P6) -> 9 | S6: =DAY(P6) -> 1 | T6: 재직 | AA6: 사원 | AB6: 38100 | AC6: 38749 | AD6: 39814 | AE6: 41275 | AJ6: 이사/실장
A7: 이상훈 | B7: =이상훈!AA3 -> 출판사업본부 | D7: =이상훈!N6 -> 53 | E7: 필 | F7: 유 | G7: 1 | I7: =이상훈!E8 -> 경기도 고양시 덕양구 | J7: =이상훈!Q19 -> 대졸 | K7: =이상훈!I20 -> 명지대학교 | L7: =이상훈!K20 -> 행정학(법학) | M7: 1002-629-089788 | N7: =O7/365 -> 17.676712 | O7: =$A$1-P7 -> 6452 | P7: =이상훈!E3 -> 39661 | Q7: =YEAR(P7) -> 2008 | R7: =MONTH(P7) -> 8 | S7: =DAY(P7) -> 1 | T7: 재직 | AA7: 과장 | AD7: 40909 | AJ7: 본부장
A8: 전연진 | B8: 연구소 | C8: =전연진!AE3 -> 개발팀 | D8: =전연진!N6 -> 46 | F8: 유 | G8: 2 | I8: =전연진!E8 -> 경기도 부천시 | J8: =전연진!Q19 -> 석사 | K8: =전연진!I20 -> 건국대 교육대학원 | L8: =전연진!L20 -> 영재교육전공 | M8: 1002-330-916674 | N8: =O8/365 -> 17.572603 | O8: =$A$1-P8 -> 6414 | P8: =전연진!E3 -> 39699 | Q8: =YEAR(P8) -> 2008 | R8: =MONTH(P8) -> 9 | S8: =DAY(P8) -> 8 | T8: 재직 | AA8: 대리 | AC8: 40909 | AJ8: 부소장
A9: 유상욱 | B9: 연구소 | C9: 스마트학습팀 | D9: =유상욱!N6 -> 47 | E9: 필 | F9: 무 | I9: =유상욱!E8 -> 경기도 하남시 | J9: =유상욱!Q19 -> 대졸 | K9: =유상욱!I20 -> 국민대학교 | L9: =유상욱!L20 -> 전자공학 | M9: 553-102619-02-001 | N9: =O9/365 -> 17.476712 | O9: =$A$1-P9 -> 6379 | P9: =유상욱!E3 -> 39734 | Q9: =YEAR(P9) -> 2008 | R9: =MONTH(P9) -> 10 | S9: =DAY(P9) -> 13 | T9: 재직 | AA9: 사원 | AB9: 40179 | AC9: 41275 | AJ9: 팀장
A10: 송재완 | B10: =송재완!AA3 -> 출판사업본부 | C10: 출판영업팀 | D10: =송재완!N6 -> 48 | E10: 필 | F10: 유 | G10: 1 | I10: =송재완!E8 -> 경기도 수원시 장안구 | J10: =송재완!Q19 -> 대졸 | K10: =송재완!I20 -> 호원대학교 | L10: =송재완!K20 -> 관광경영학 | M10: 1002-738-307629 | N10: =O10/365 -> 17.4 | O10: =$A$1-P10 -> 6351 | P10: =송재완!E3 -> 39762 | Q10: =YEAR(P10) -> 2008 | R10: =MONTH(P10) -> 11 | S10: =DAY(P10) -> 10 | T10: 재직 | AA10: 대리 | AC10: 40909 | AJ10: 팀장
A11: 양현미 | B11: 학원사업본부 | C11: 직영관리팀 | D11: =양현미!N6 -> 49 | F11: 무 | I11: =양현미!E8 -> 서울시 성북구 | J11: 대졸 | K11: =양현미!I20 -> 상명대학교 | L11: =양현미!L20 -> 지리학 | M11: 136-330232-02-001 | N11: =O11/365 -> 16.172603 | O11: =$A$1-P11 -> 5903 | P11: =양현미!E3 -> 40210 | Q11: =YEAR(P11) -> 2010 | R11: =MONTH(P11) -> 2 | S11: =DAY(P11) -> 1 | T11: 재직 | AA11: 대리 | AC11: 40909 | AJ11: 팀장
A12: 심종주 | B12: =심종주!AA3 -> 경영총괄실 | C12: 경영지원팀 | D12: =심종주!N6 -> 42 | E12: 필 | F12: 유 | G12: 2 | I12: =심종주!E8 -> 경기도 파주시 | J12: =심종주!Q19 -> 대졸 | K12: =심종주!I19 -> 한성대학교 | L12: =심종주!L19 -> 경영학과 | M12: 1002-833-919565 | N12: =O12/365 -> 16.131507 | O12: =$A$1-P12 -> 5888 | P12: =심종주!E3 -> 40225 | Q12: =YEAR(P12) -> 2010 | R12: =MONTH(P12) -> 2 | S12: =DAY(P12) -> 16 | T12: 재직 | AA12: 사원 | AB12: 41275 | AJ12: 팀장
A13: 박민정 | B13: =박민정!AA3 -> 경영총괄실 | C13: 경영지원팀 | D13: =박민정!N6 -> 39 | F13: 무 | I13: =박민정!E8 -> 충북 보은군 보은읍 | J13: =박민정!Q19 -> 대졸 | K13: =박민정!I19 -> 한남대학교 | L13: =박민정!L19 -> 수학과 | M13: 1002-743-189595 | N13: =O13/365 -> 15.309589 | O13: =$A$1-P13 -> 5588 | P13: =박민정!E3 -> 40525 | Q13: =YEAR(P13) -> 2010 | R13: =MONTH(P13) -> 12 | S13: =DAY(P13) -> 13 | T13: 재직 | AA13: 사원 | AE13: 41640
A14: 김진형 | B14: 학원사업본부 | C14: 가맹영업팀 | D14: =김진형!N6 -> 42 | E14: 필 | F14: 유 | G14: 1 | I14: =김진형!E8 -> 서울특별시 은평구 진관동 22 | J14: =김진형!Q19 -> 대졸 | K14: =김진형!I20 -> TSING HUA UNI. | L14: =김진형!K20 -> 중어중문 | M14: 1002-837-329790 | N14: =O14/365 -> 12.490411 | O14: =$A$1-P14 -> 4559 | P14: =김진형!E3 -> 41554 | Q14: =YEAR(P14) -> 2013 | R14: =MONTH(P14) -> 10 | S14: =DAY(P14) -> 7 | T14: 재직 | AA14: 사원 | AJ14: 팀장
A15: 김숙희 | B15: 연구소 | C15: =김숙희!AE3 -> 개발팀 | D15: =김숙희!N6 -> 37 | F15: 무 | I15: =김숙희!E8 -> 서울 송파구 오륜동 | J15: =김숙희!Q19 -> 학사 | K15: =김숙희!I20 -> 서울여자대학교 | L15: =김숙희!K20 -> 수학과 | M15: 1002-235-668776 | N15: =김숙희!N7 -> 12.093151 | O15: =$A$1-P15 -> 4414 | P15: =김숙희!E3 -> 41699 | Q15: 2014 | R15: 3 | S15: 1 | T15: 재직 | AA15: 사원
A16: 김소라 | B16: 연구소 | C16: 이러닝디자인팀 | D16: =김소라!N6 -> 38 | F16: 유 | G16: 1 | I16: =김소라!E8 -> 서울시 중랑구 | J16: =김소라!Q19 -> 학사 | K16: =김소라!I20 -> 강원대학교 | L16: =김소라!K20 -> 생명공학과 | M16: 1002-551-003339 | N16: =김소라!N7 -> 12.030137 | O16: =$A$1-P16 -> 4391 | P16: =김소라!E3 -> 41722 | Q16: 2014 | R16: 3 | S16: 24 | T16: 재직 | AA16: 사원
A17: 오우림 | B17: =오우림!AA3 -> 학원사업본부 | C17: =오우림!AE3 -> 가맹영업팀 | D17: =오우림!N6 -> 36 | E17: 필 | F17: 유 | G17: 2 | I17: =오우림!E8 -> 경기도 수원시 팔당구 | J17: =오우림!Q19 -> 대졸 | K17: =오우림!I20 -> 건국대학교 | L17: =오우림!K20 -> 생명공학 | M17: 1002-354-559313 | N17: =오우림!N7 -> 10.421918 | O17: =$A$1-P17 -> 3804 | P17: =오우림!E3 -> 42309 | Q17: 2015 | R17: 11 | S17: 1 | T17: 재직 | AA17: 사원
A18: 박미영 | B18: 연구소 | C18: 이러닝디자인팀 | D18: =박미영!N6 -> 52 | F18: 무 | I18: =박미영!E8 -> 서울특별시 송파구 | J18: =박미영!Q19 -> 대졸 | K18: =박미영!I20 -> 인천대학교 | L18: =박미영!K20 -> 영어과 | M18: 1002-756-804471 | N18: =박미영!N7 -> 9.0383562 | O18: =$A$1-P18 -> 3299 | P18: 42814 | Q18: 2017 | R18: 3 | S18: 20 | T18: 재직
A19: 이동희 | B19: =이동희!AA3 -> 연구소 | C19: =이동희!AE3 -> IT디자인팀 | D19: =이동희!N6 -> 34 | F19: 무 | I19: =이동희!E8 -> 서울시 도봉구 | J19: =이동희!Q19 -> 대졸 | K19: =이동희!I19 -> 동덕여대 | L19: =이동희!L19 -> 국문학 | N19: =O19/365 -> 8.7561644 | O19: =$A$1-P19 -> 3196 | P19: 42917 | Q19: 2017 | R19: 7 | S19: 1 | T19: 재직 | AA19: 사원
A20: 허철우 | B20: =허철우!AA3 -> 연구소 | C20: =허철우!AE3 -> IT디자인팀 | D20: =허철우!N6 -> 35 | E20: 필 | F20: 무 | I20: =허철우!E8 -> 경기도 성남시 | J20: =허철우!Q19 -> 대졸 | K20: =허철우!I19 -> 한국교통대학교 | L20: =허철우!L19 -> 전자공학과 | N20: =O20/365 -> 8.290411 | O20: =$A$1-P20 -> 3026 | P20: 43087 | Q20: 2017 | R20: 12 | S20: 18 | T20: 재직
A21: 장호경 | B21: =장호경!AA3 -> 연구소 | C21: =장호경!AE3 -> 스마트학습팀 | D21: =장호경!N6 -> 36 | E21: 필 | F21: 무 | I21: =장호경!E8 -> 인천광역시 서구 | J21: =장호경!Q19 -> 석사 | K21: =장호경!I20 -> 성균관대학교 대학원 | L21: =장호경!L20 -> 수학교육 | N21: =O21/365 -> 7.0630137 | O21: =$A$1-P21 -> 2578 | P21: 43535 | Q21: 2019 | R21: 3 | S21: 11 | T21: 재직
A22: 김현종 | B22: =김현종!AA3 -> 연구소 | C22: =김현종!AE3 -> IT디자인팀 | D22: =김현종!N6 -> 34 | E22: 필 | F22: 무 | I22: =김현종!E8 -> 서울특별시 마포구 | J22: =김현종!Q19 -> 대졸 | K22: =김현종!I19 -> 카톨릭대학교 | L22: =김현종!L19 -> 정보통신전자공학 | N22: =O22/365 -> 5.8356164 | O22: =$A$1-P22 -> 2130 | P22: 43983 | Q22: 2020 | R22: 6 | S22: 1 | T22: 재직
A23: 구자홍 | B23: =구자홍!AA3 -> 연구소 | C23: =구자홍!AE3 -> 스마트학습 | D23: =구자홍!N6 -> 39 | E23: 필 | F23: 유 | I23: =구자홍!E8 -> 서울특별시 강동구 | J23: =구자홍!Q19 -> 석사 | K23: =구자홍!I19 -> 성균관대학교 | L23: =구자홍!L19 -> 수학교육 | N23: =O23/365 -> 4.3205479 | O23: =$A$1-P23 -> 1577 | P23: 44536 | Q23: 2021 | R23: 12 | S23: 6 | T23: 재직
A24: 지성구 | B24: =지성구!AA3 -> 경영총괄실 | C24: =지성구!AE3 -> 물류팀 | D24: =지성구!N6 -> 48 | E24: 필 | F24: 유 | G24: 2 | I24: =지성구!E8 -> 경기도 고양시 일산동구 | J24: =지성구!Q19 -> 대졸 | K24: =지성구!I19 -> 가천대학교 | L24: =지성구!L19 -> 체육전문학 | N24: =O24/365 -> 3.6493151 | O24: =$A$1-P24 -> 1332 | P24: 44781 | Q24: 2022 | R24: 8 | S24: 8 | T24: 재직
A25: 최준석 | B25: =최준석!AA3 -> 경영총괄실 | C25: =최준석!AE3 -> 물류팀 | D25: =최준석!N6 -> 43 | E25: 필 | F25: 유 | I25: =최준석!E8 -> 경기도 김포시 | J25: =최준석!Q19 -> 초대졸 | K25: =최준석!I19 -> 동국대 전산원 | L25: =최준석!L19 -> 인터넷정보 | N25: =O25/365 -> 3.5835616 | O25: =$A$1-P25 -> 1308 | P25: 44805 | Q25: 2022 | R25: 9 | S25: 1 | T25: 재직 | AJ25: 팀장
A26: 손주호 | B26: =손주호!AA3 -> 학원사업본부 | C26: =손주호!AE3 -> 가맹사업팀 | D26: =손주호!N6 -> 37 | E26: 필 | F26: 무 | I26: =손주호!E8 -> 서울시 동작구 | J26: =손주호!Q19 -> 대졸 | K26: =손주호!I19 -> 대구대학교 | L26: =손주호!L19 -> 생명공학과 | N26: =손주호!N7 -> 3.0931507 | O26: =$A$1-P26 -> 1129 | P26: =손주호!E3 -> 44984 | Q26: 2023 | R26: 2 | S26: 27 | T26: 재직
A27: 김연경 | B27: =김연경!AA3 -> 연구소 | C27: =김연경!AE3 -> IT디자인팀 | D27: =김연경!N6 -> 29 | F27: 무 | I27: =김연경!E8 -> 경기도 하남시 | J27: =김연경!Q21 -> 대졸 | K27: =김연경!I21 -> 배재대학교 | L27: =김연경!L21 -> 중국학과 | N27: =김연경!N7 -> 3.0931507 | O27: =$A$1-P27 -> 1129 | P27: =김연경!E3 -> 44984 | Q27: 2023 | R27: 2 | S27: 27 | T27: 재직
A28: 한정규 | B28: =한정규!AA3 -> 신사업본부 | D28: =한정규!N6 -> 33 | E28: 필 | F28: 유 | I28: =한정규!E8 -> 서울시 용산구 | N28: =한정규!N7 -> 2.5835616 | O28: =$A$1-P28 -> 943 | P28: =한정규!E3 -> 45170 | Q28: 2023 | R28: 9 | S28: 1 | T28: 재직
A29: =최정우!E5 -> 최정우 | B29: =최정우!AA3 -> 경영총괄실 | C29: =최정우!AE3 -> 경영지원팀 | D29: =최정우!N6 -> 31 | E29: 필 | F29: 무 | I29: =최정우!E8 -> 경기도 광명시 | J29: =최정우!Q19 -> 대졸 | K29: =최정우!I19 -> 카톨릭대학교 | L29: =최정우!L19 -> 국어국문 | N29: =최정우!N7 -> 1.4246575 | O29: =$A$1-P29 -> 520 | P29: =최정우!E3 -> 45593 | Q29: 2024 | R29: 10 | S29: 28 | T29: 재직
A30: =이준호!E5 -> 이준호 | B30: =이준호!AA3 -> 경영총괄실 | D30: =이준호!N6 -> 34 | E30: 필 | F30: 유 | I30: =이준호!E8 -> 서울시 중랑구 | J30: =이준호!Q19 -> 대졸 | K30: =이준호!I20 -> Boston University | L30: =이준호!L20 -> chemistry | N30: =이준호!N7 -> 1.2438356 | O30: =$A$1-P30 -> 454 | P30: =이준호!E3 -> 45659 | Q30: 2025 | R30: 1 | S30: 2 | T30: 재직
A31: =이영주!E5 -> 이영주 | B31: =이영주!AA3 -> 연구소 | C31: =이영주!AE3 -> 개발팀 | D31: =이영주!N6 -> 25 | F31: 무 | I31: =이영주!E8 -> 서울시 강북구 | J31: =이영주!Q19 -> 대졸 | K31: =이영주!I19 -> 서울여자대학교 | L31: =이영주!L19 -> 수학과 | N31: =이영주!N7 -> 1.1616438 | O31: =$A$1-P31 -> 424 | P31: =이영주!E3 -> 45689 | Q31: 2025 | R31: 2 | S31: 1 | T31: 재직
A32: =진하람!E5 -> 진하람 | B32: =진하람!AA3 -> 연구소 | C32: =진하람!AE3 -> 개발팀 | D32: =진하람!N6 -> 33 | E32: 필 | F32: 무 | I32: =진하람!E8 -> 서울시 동대문구 | J32: =진하람!Q19 -> 대졸 | K32: =진하람!I19 -> 한양대학교 | L32: =진하람!L19 -> 수학과 | N32: =진하람!N7 -> 1.1616438 | O32: =$A$1-P32 -> 424 | P32: =진하람!E3 -> 45689 | Q32: 2025 | R32: 2 | S32: 1 | T32: 재직
A33: =김태경!E5 -> 김태경 | B33: =김태경!AA3 -> 경영총괄실 | C33: =김태경!AE3 -> 물류팀 | D33: =김태경!N6 -> 64 | E33: 필 | F33: 유 | I33: =김태경!E8 -> 경기도 파주시 | N33: =김태경!N7 -> 1 | O33: =$A$1-P33 -> 365 | P33: =김태경!E3 -> 45748 | Q33: 2025 | R33: 4 | S33: 1 | T33: 재직
A34: 조성아 | B34: =조성아_퇴사!AA3 -> 학원사업본부 | C34: =조성아_퇴사!AE3 -> 직영관리팀 | D34: =조성아_퇴사!N6 -> 35 | F34: 유 | G34: 1 | I34: =조성아_퇴사!E8 -> 서울시 광진구 | J34: =조성아_퇴사!Q19 -> 대졸 | K34: =조성아_퇴사!I19 -> 서울여자대학교 | L34: =조성아_퇴사!L19 -> 국문학 | N34: =O34/365 -> 8.1041096 | O34: =$A$1-P34 -> 2958 | P34: 43155 | Q34: 2018 | R34: 2 | S34: 24 | T34: 퇴직 | U34: =조성아_퇴사!O3 -> 45620 | V34: 2024 | W34: 11 | X34: 24 | Y34: 육아
A35: 최철호 | B35: =최철호!AA3 -> 출판사업본부 | C35: 가맹영업팀 | D35: =최철호!N6 -> 61 | E35: 필 | F35: 유 | G35: 2 | I35: =최철호!E8 -> 경기도 고양시 일산동구 | J35: =최철호!Q19 -> 대졸 | K35: =최철호!I19 -> 서울대학교 | L35: =최철호!L19 -> 수학과 | M35: 1002-344-746439 | N35: =O35/365 -> 14.676712 | O35: =$A$1-P35 -> 5357 | P35: =최철호!E3 -> 40756 | Q35: =YEAR(P35) -> 2011 | R35: =MONTH(P35) -> 8 | S35: =DAY(P35) -> 1 | T35: 퇴직 | U35: 45808 | V35: 2025 | W35: 5 | X35: 31 | Y35: 계약직 전환 | AA35: 이사 | AJ35: 이사
A36: =황대위_퇴사!E5 -> 황대위 | B36: =황대위_퇴사!AA3 -> 출판사업본부 | D36: =황대위_퇴사!N6 -> 33 | E36: 면제 | F36: 무 | I36: =황대위_퇴사!E8 -> 서울시 중랑구 묵동 | J36: =황대위_퇴사!Q19 -> 대졸 | K36: =황대위_퇴사!I19 -> 동서울대학 | L36: =황대위_퇴사!L19 -> 정보통신 | N36: =황대위_퇴사!N7 -> 1.0849315 | O36: =$A$1-P36 -> 396 | P36: =황대위_퇴사!E3 -> 45717 | Q36: 2025 | R36: 3 | S36: 1 | T36: 퇴직 | U36: =황대위_퇴사!O3 -> 45869 | V36: 2025 | W36: 7 | X36: 31 | Y36: 이직
A37: 이화종 | B37: =이화종_퇴사!AA3 -> 학원사업본부 | C37: =이화종_퇴사!AE3 -> 가맹사업팀 | D37: =이화종_퇴사!N6 -> 48 | E37: 필 | F37: 유 | I37: =이화종_퇴사!E8 -> 경기도 부천시 | J37: =이화종_퇴사!Q19 -> 대졸 | K37: =이화종_퇴사!I19 -> 상지대 | L37: =이화종_퇴사!L19 -> 국문학 | N37: =O37/365 -> 8.4438356 | O37: =$A$1-P37 -> 3082 | P37: 43031 | Q37: 2017 | R37: 10 | S37: 23 | T37: 퇴직 | U37: =이화종_퇴사!O3 -> 45471 | V37: 2024 | W37: 6 | X37: 28 | Y37: 이직 | AJ37: 팀장
A38: 김문수 | B38: =김문수_퇴사!AA3 -> 경영총괄실 | C38: =김문수_퇴사!AE3 -> 물류팀 | D38: =김문수_퇴사!N6 -> 62 | E38: 필 | F38: 유 | G38: 2 | I38: =김문수_퇴사!E8 -> 서울 강동구 | J38: =김문수_퇴사!Q19 -> 대졸 | K38: =김문수_퇴사!I19 -> 한양대학교 | L38: =김문수_퇴사!L19 -> 재료공학과 | N38: =O38/365 -> 3.5835616 | O38: =$A$1-P38 -> 1308 | P38: 44805 | Q38: 2022 | R38: 9 | S38: 1 | T38: 퇴직 | U38: =김문수_퇴사!O3 -> 45545 | V38: 2024 | W38: 9 | X38: 10 | Y38: 질병
A39: 강규영 | B39: =강규영_퇴사!AA3 -> 연구소 | C39: =강규영_퇴사!AE3 -> 개발팀 | D39: =강규영_퇴사!N6 -> 29 | F39: 무 | I39: =강규영_퇴사!E8 -> 경기도 남양주시 | J39: =강규영_퇴사!Q19 -> 대졸 | K39: =강규영_퇴사!I19 -> 연세대학교 미래캠퍼스 | L39: =강규영_퇴사!L19 -> 수학과 | N39: =강규영_퇴사!N7 -> 3.0931507 | O39: =$A$1-P39 -> 1129 | P39: =강규영_퇴사!E3 -> 44984 | Q39: 2023 | R39: 2 | S39: 27 | T39: 퇴직 | U39: =강규영_퇴사!O3 -> 45583 | V39: 2024 | W39: 10 | X39: 18 | Y39: 기타
A40: 이승희 | B40: =이승희_퇴사!AA3 -> 연구소 | C40: =이승희_퇴사!AE3 -> 개발2팀 | D40: =이승희_퇴사!N6 -> 34 | E40: 필 | F40: 무 | I40: =이승희_퇴사!E8 -> 서울시 동작구 | J40: =이승희_퇴사!Q19 -> 대졸 | K40: =이승희_퇴사!I20 -> Boston University | L40: =이승희_퇴사!L20 -> chemistry | N40: =O40/365 -> 7.8383562 | O40: =$A$1-P40 -> 2861 | P40: =이승희_퇴사!E3 -> 43252 | Q40: 2018 | R40: 6 | S40: 1 | T40: 퇴직 | U40: 44958 | V40: 2023 | W40: 2 | X40: 1 | Y40: 기타 | AA40: 팀장
A41: 안영일 | B41: 연구소 | C41: 이러닝디자인팀 | D41: =안영일_퇴사!N6 -> 54 | E41: 필 | F41: 무 | I41: =안영일_퇴사!E8 -> 서울시 중랑구 중화1동 | J41: =안영일_퇴사!Q19 -> 대졸 | K41: =안영일_퇴사!I19 -> 서울시립대학교 | L41: =안영일_퇴사!L19 -> 제어계측 | M41: 1002-281-052571 | N41: =O41/365 -> 16.172603 | O41: =$A$1-P41 -> 5903 | P41: =안영일_퇴사!E3 -> 40210 | Q41: =YEAR(P41) -> 2010 | R41: =MONTH(P41) -> 2 | S41: =DAY(P41) -> 1 | T41: 퇴직 | U41: 45245 | V41: 2023 | W41: 11 | X41: 15 | Y41: 이직 | AA41: 차장 | AE41: 41640 | AJ41: 부소장
...

Sheet 입퇴사현황
A5: 2020년 | B5: 1월 | C5: 2월 | D5: 3월 | E5: 4월 | F5: 5월 | G5: 6월 | H5: 7월 | I5: 8월 | J5: 9월 | K5: 10월 | L5: 11월 | M5: 12월 | N5: 평균직원
A6: 본사 정규 | B6: 30 | C6: 30 | D6: 30 | E6: 30 | F6: 30 | G6: 31 | H6: 31 | I6: 31 | J6: 32 | K6: 32 | L6: 32 | M6: 31 | N6: =AVERAGE(B8:M8) -> 31.083333
A7: 본사 계약 | B7: 0 | C7: 0 | D7: 0 | E7: 0 | F7: 0 | G7: 0 | H7: 0 | I7: 0 | J7: 0 | K7: 1 | L7: 1 | M7: 1
A8: 계 | B8: =SUM(B6:B7) -> 30 | C8: =SUM(C6:C7) -> 30 | D8: =SUM(D6:D7) -> 30 | E8: =SUM(E6:E7) -> 30 | F8: =SUM(F6:F7) -> 30 | G8: =SUM(G6:G7) -> 31 | H8: =SUM(H6:H7) -> 31 | I8: =SUM(I6:I7) -> 31 | ... M8: =SUM(M6:M7) -> 32
A9: 입사 | G9: 김현종 | J9: 김종순 | K9: 김미성 | N9: 총 입사 | O9: 3
A10: 퇴사 | M10: 심순자 | N10: 총 퇴사 | O10: 1
N11: 퇴직율 | O11: =O10/N6 -> 0.032171582
A13: 2020년 | B13: 1월 | C13: 2월 | D13: 3월 | E13: 4월 | F13: 5월 | G13: 6월 | H13: 7월 | I13: 8월 | J13: 9월 | K13: 10월 | L13: 11월 | M13: 12월 | N13: 평균직원
A14: 직영 정규 | B14: 16 | C14: 15 | D14: 16 | E14: 16 | F14: 15 | G14: 15 | H14: 16 | I14: 17 | J14: 17 | K14: 17 | L14: 16 | M14: 16 | N14: =AVERAGE(B14:M14) -> 16
A15: 입사 | D15: 안혜진 | E15: 김민아 | H15: 김지민 | I15: 연은진 | N15: 총 입사 | O15: 5
A16: 퇴사 | C16: 임지은 | E16: 채민아 | F16: 이혜림 | L16: 김예영 | N16: 총 퇴사 | O16: 3
N17: 퇴직율 | O17: =(O16/N14) -> 0.1875
A20: 2021년 | B20: 1월 | C20: 2월 | D20: 3월 | E20: 4월 | F20: 5월 | G20: 6월 | H20: 7월 | I20: 8월 | J20: 9월 | K20: 10월 | L20: 11월 | M20: 12월 | N20: 평균직원
A21: 본사 정규 | B21: 31 | C21: 31 | D21: 30 | E21: 30 | F21: 30 | G21: 30 | H21: 30 | I21: 30 | J21: 30 | K21: 29 | L21: 29 | M21: 30 | N21: =AVERAGE(B23:M23) -> 30.75
A22: 본사 계약 | B22: 1 | C22: 1 | D22: 1 | E22: 1 | F22: 1 | G22: 1 | H22: 1 | I22: 1 | J22: 1 | K22: 0 | L22: 0 | M22: 0
A23: 계 | B23: =SUM(B21:B22) -> 32 | C23: =SUM(C21:C22) -> 32 | D23: =SUM(D21:D22) -> 31 | E23: =SUM(E21:E22) -> 31 | F23: =SUM(F21:F22) -> 31 | G23: =SUM(G21:G22) -> 31 | H23: =SUM(H21:H22) -> 31 | I23: =SUM(I21:I22) -> 31 | ... M23: =SUM(M21:M22) -> 30
A24: 입사 | M24: 구자홍 | N24: 총 입사 | O24: 1
A25: 퇴사 | D25: 김문수 | K25: 유기선, 김미성 | N25: 총 퇴사 | O25: 3
N26: 퇴직율 | O26: =O25/N21 -> 0.097560976
A28: 2021년 | B28: 1월 | C28: 2월 | D28: 3월 | E28: 4월 | F28: 5월 | G28: 6월 | H28: 7월 | I28: 8월 | J28: 9월 | K28: 10월 | L28: 11월 | M28: 12월 | N28: 평균직원
A29: 직영 정규 | B29: 17 | C29: 17 | D29: 17 | E29: 16 | F29: 14 | G29: 14 | H29: 15 | I29: 14 | J29: 14 | K29: 16 | L29: 16 | M29: 15 | N29: =AVERAGE(B29:M29) -> 15.416667
A30: 입사 | B30: 동백 안수인 | H30: 중등 최초원 | K30: 대치 김다예 대치 김소연 | N30: 총 입사 | O30: 4
A31: 퇴사 | E31: 잠실 김지민 | F31: 잠실 김숙영 잠실 순지혜 | I31: 중계 연은진 | M31: 중등 박상글 중등 최초원 | N31: 총 퇴사 | O31: 6
N32: 퇴직율 | O32: =O31/N29 -> 0.38918919
A33: 2022년 입퇴사 현황(본사/직영)
A35: 2022년 | B35: 1월 | C35: 2월 | D35: 3월 | E35: 4월 | F35: 5월 | G35: 6월 | H35: 7월 | I35: 8월 | J35: 9월 | K35: 10월 | L35: 11월 | M35: 12월 | N35: 평균직원
A36: 본사 정규 | B36: 30 | C36: 30 | D36: 30 | E36: 30 | F36: 28 | G36: 28 | H36: 27 | I36: 28 | J36: 30 | K36: 30 | L36: 32 | M36: 32 | N36: =AVERAGE(B37:M37) -> 29.583333
A37: 계 | B37: =SUM(B36:B36) -> 30 | C37: =SUM(C36:C36) -> 30 | D37: =SUM(D36:D36) -> 30 | E37: =SUM(E36:E36) -> 30 | F37: =SUM(F36:F36) -> 28 | G37: =SUM(G36:G36) -> 28 | H37: 27 | I37: 28 | J37: 30 | K37: 30 | L37: 32 | M37: 32
A38: 입사 | I38: 지성구 | J38: 최준석 김문수 | L38: 최문희 변혜진 이승희 | N38: 총 입사 | O38: 6
A39: 퇴사 | F39: 박대헌 이승희 | H39: 김길중 | L39: 안다애 | N39: 총 퇴사 | O39: 4
N40: 퇴직율
A42: 2022년 | B42: 1월 | C42: 2월 | D42: 3월 | E42: 4월 | F42: 5월 | G42: 6월 | H42: 7월 | I42: 8월 | J42: 9월 | K42: 10월 | L42: 11월 | M42: 12월 | N42: 평균직원
A43: 직영 정규 | B43: 17 | C43: 18 | D43: 18 | E43: 19 | F43: 19 | G43: 19 | H43: 18 | I43: 19 | J43: 20 | K43: 20 | L43: 20 | M43: 20 | N43: =AVERAGE(B43:M43) -> 18.916667
A44: 입사 | B44: 중계 강애리 중계 안유연 | C44: 중등 윤영준 | E44: 동탄 공선경 잠실 홍아름 | F44: 중등 한수진 | H44: 중계 박준희 | I44: 잠실 이채윤 | J44: 대치 박인재 | N44: 총 입사 | O44: 9
A45: 퇴사 | E45: 대치 김소연 | F45: 잠실 백혜진 | H45: 동백 안혜진 대치 이지희 | N45: 총 퇴사 | O45: 4
N47: 퇴직율 | O47: =O45/N43 -> 0.21145374
A49: 2023년 입퇴사 현황(본사/직영)
A51: 2023년 | B51: 1월 | C51: 2월 | D51: 3월 | E51: 4월 | F51: 5월 | G51: 6월 | H51: 7월 | I51: 8월 | J51: 9월 | K51: 10월 | L51: 11월 | M51: 12월 | N51: 평균직원
A52: 본사 정규 | B52: 32 | C52: 31 | D52: 31 | E52: 31 | F52: 31 | G52: 31 | H52: 31 | I52: 31 | J52: 32 | K52: 31 | L52: 30 | M52: 30 | N52: =AVERAGE(B52:M52) -> 31
A53: 입사 | C53: 강규영 김연경 손주호 | J53: 한정규 | N53: 총 입사 | O53: 4
...

Sheet 년별 입퇴사 현황
A1: 년도 별 입, 퇴사자 현황
B2: 2011년 | C2: 2012년 | D2: 2013년 | E2: 2014년 | F2: 2015년 | G2: 2016년 | H2: 2017년 | I2: 2018년 | J2: 2019년 | K2: 2020년 | L2: 2021년 | M2: 2022년 | N2: 2023년 | O2: 2024년 | P2: 2025년
A3: 입사자 | B3: 최철호(08.01) | C3: 박여진(01.01) | D3: 김형인(04.15) | E3: 김세영(01.01) | F3: 오우림(11.01) | H3: 원혜인(2.14) | I3: 조성아(2.23) | J3: 박대헌(2.11) | K3: 김현종(6.1) | L3: 구자홍(12.6) | M3: 지성구(8.8) | N3: 강규영(1.27) | O3: 최정우(10.28) | P3: 이준호(1.2)
B4: 김용권(08.29) | C4: 정혜영(01.02) | D4: 박용희(06.17) | E4: 심순자(03.01) | H4: 박미영(3.20) | I4: 유기선(2.23) | J4: 김문수(12.1) | K4: 김종순(9.7) | M4: 최준석(9.1) | N4: 김연경(1.27) | P4: 이영주(2.1)
B5: 유종찬(11.01) | C5: 이종명(01.25) | D5: 배은서(06.17) | E5: 김숙희(03.01) | H5: 이동희(7.1) | I5: 이승희(6.1) | M5: 김문수(9.1) | N5: 손주호(1.27) | P5: 진하람(2.1)
C6: 정호은(01.25) | D6: 김진형(10.07) | E6: 마세영(03.17) | H6: 이화종(10.23) | N6: 한정규(9.1) | P6: 황대위(3.1)
C7: 전선민(01.25) | D7: 명수진(10.07) | E7: 김소라(03.24) | H7: 최준석(10.23) | P7: 김태경(4.1)
C8: 이유미(02.20) | D8: 김란아(10.07) | E8: 정용상(09.01) | P8: 이윤희(5.1)
C9: 박종주(02.06)
C10: 강철구(02.06)
C11: 오준영(03.05)
C12: 조진성(10.25)
C13: 김경열(12.10)
C14: 박대헌(12.10)
A16: 퇴사자 | B16: 임현(05.31) | C16: 이훈민(01.31) | D16: 김현주(02.28) | E16: 강재석(02.28) | F16: 이종명(1.25) | G16: 명수진(1.22) | H16: 마세영(3.10) | I16: 박대헌(1.10) | J16: 이유미(12.31) | K16: 심순자(12.31) | L16: 김문수(3.1) | M16: 박대헌(4.30) | N16: 최문희(2.10) | O16: 이화종(6.28) | P16: 최철호(5.31)
B17: 황석연(10.30) | C17: 김혜진(03.10) | D17: 김희진(03.31) | E17: 유종찬(03.31) | F17: 최보나(4.01) | H17: 김형인(5.16) | I17: 이치영(1.31) | J17: 원혜인(2.28) | K17: 이우기(1.31) | L17: 유기선(11.1) | M17: 이승희(5.31) | N17: 변혜진(2.1) | O17: 김문수(9.10) | P17: 황대위(7.31)
B18: 이재호(10.30) | C18: 전선민(07.31) | D18: 조진성(05.08) | E18: 김란아(07.22) | F18: 정혜영(4.30) | H18: 강철구(8.30) | I18: 정용상(12.31) | M18: 김길중(6.30) | N18: 이승희(2.1) | O18: 강규영(10.18)
B19: 김형인(12.05) | C19: 왕준표(07.31) | D19: 이응희(05.31) | E19: 김세영(07.31) | F19: 배은서(4.29) | H19: 김용권(6.30) | I19: 김재근(7.19) | N19: 박유린(2.1) | O19: 조성아(11.24)
B20: 최세별(12.07) | C20: 이항녕(11.26) | D20: 김경열(06.05) | E20: 박용희(11.30) | F20: 유민재(7.01) | N20: 김종순(10.28)
B21: 김설화(12.30) | D21: 강민영(06.30) | E21: 노정현(11.30) | F21: 김민식(8.31) | N21: 안영일
B22: 신광용(11.30) | D22: 정호은(07.31) | F22: 오준영(10.15)
D23: 박종주(11.08)
D24: 박여진(12.13)
D25: 이지현(12.17)
D26: 최보나(12.31)

Sheet 조경희
B1: 직원 인사 기록 카드
B2: =TODAY() -> 46113
B3: 입 사 일 자 | E3: 36770 | L3: 퇴 사 일 자 | W3: 소속본부 및 팀 | AA3: 연구소
B5: 이 름 | E5: 조 경 희 | L5: 종 교 | N5: 불교 | R5: 사 진
B6: 생 년 월 일 | E6: 23751 | L6: 나 이 | N6: =DATEDIF(E6,TODAY(),"y") -> 61
B7: 주민등록번호 | E7: 650109-2011122 | L7: 근속연수 | N7: =(B2-E3)/365 -> 25.59726
B8: 현 주 소 | E8: 서울시 마포구 | K8: 독막로 28길 10 밤섬경남아너스빌 103동 1801호
B9: 거 주 지 | E9: 서울시 마포구 독막로 28길 10 밤섬경남아너스빌 103동 1801호
B10: 전 화 번 호 | E10: 010-5264-1390 | M10: 결혼유무
B11: 자 격 사 항 | E11: 종 류 | J11: 취 득 일 | O11: 특 기
B15: 병 력 사 항
E16: 기 간 | N16: 최종 계급
E17: 군 별 | N17: 병 과
B18: 학 력 | E18: 기 간 | I18: 학교 및 전공 | N18: 졸업년월 | Q18: 최종학력
E19: 1983.03 ~ 1987.02 | I19: 서울대학교 | L19: 계산통계학 | N19: 1987.02 | Q19: 대졸
B23: 경 력 | E23: 재 직 기 간 | K23: 근 무 부 서 | N23: 직 장 명 | P23: 직 위 | R23: 근 무 년 수
E24: 32905 | H24: 33969 | K24: CBE개발부 | N24: 웅진미디어 | P24: 연구원 | R24: =(H24-E24)/365 -> 2.9150685
E25: 34182 | H25: 34699 | K25: 개발부 | N25: 성일정보통신 | P25: 팀장 | R25: =(H25-E25)/365 -> 1.4164384
E26: 34700 | H26: 35430 | K26: 과학개발팀 | N26: 김영사 | P26: 팀장 | R26: =(H26-E26)/365 -> 2
E27: 35431 | H27: 36160 | K27: 초등수학 | N27: 아인투과학교실 | P27: 강사 | R27: =(H27-E27)/365 -> 1.9972603
E28: 36161 | H28: 36891 | K28: 연구개발부 | N28: 뫼비우스 | P28: 실장 | R28: =(H28-E28)/365 -> 2
P29: 경력합계 | R29: =SUM(R24:T28) -> 10.328767
B30: 가 족 사 항 | E30: 성 명 | H30: 관 계 | J30: 생년월일 | M30: 직 업 | P30: 학력 | S30: 비고
E31: 이충기 | H31: 배우자 | J31: 23047 | M31: 사업 | P31: 대학원졸
E32: 이승희 | H32: 자 | J32: 33615 | P32: 학생
E33: 이하연 | H33: 자 | J33: 34086 | P33: 학생

Sheet 김우찬
B1: 직원 인사 기록 카드
B2: =TODAY() -> 46113
B3: 입 사 일 자 | E3: 37288 | L3: 퇴 사 일 자 | W3: 소속본부 및 팀 | AA3: 학원사업본부
B5: 이 름 | E5: 김 우 찬 | L5: 종 교 | N5: 천주교 | R5: 사 진
B6: 생 년 월 일 | E6: 27988 | L6: 나 이 | N6: =DATEDIF(E6,TODAY(),"y") -> 49
B7: 주민등록번호 | E7: 760816-1018913 | L7: 근속연수 | N7: =(B2-E3)/365 -> 24.178082
B8: 현 주 소 | E8: 서울시 영등포구 | K8: 당산로41길 23 106동 1207호
B9: 거 주 지 | E9: 서울 영등포구 당산로41길 23 106동 1207호
B10: 전 화 번 호 | E10: 02-2679-3166 | M10: 결혼유무
B11: 자 격 사 항 | E11: 종 류 | J11: 취 득 일 | O11: 특 기 | R11: 컴퓨터
E12: 운전면허 1종 보통 | J12: 1995.08
E13: 정보처리 산업기사 | J13: 2000.02
B15: 병 력 사 항
E16: 기 간 | G16: 97-10~99-12 | N16: 최종 계급 | Q16: 병장
E17: 군 별 | G17: 육군 | N17: 병 과 | Q17: 106M
B18: 학 력 | E18: 기 간 | I18: 학교 및 전공 | N18: 졸업년월 | Q18: 최종학력
E19: 93.2~95.2 | I19: 여의도 고등학교 | N19: 1995.2 | Q19: 대졸
E20: 97.2~2002.2 | I20: 숭실대학교 | L20: 전산원 | N20: 2002.2
B23: 경 력 | E23: 재 직 기 간 | K23: 근 무 부 서 | N23: 직 장 명 | P23: 직 위 | R23: 근 무 년 수
R24: =(H24-E24)/365 -> 0
R25: =(H25-E25)/365 -> 0
R26: =(H26-E26)/365 -> 0
R27: =(H27-E27)/365 -> 0
R28: =(H28-E28)/365 -> 0
P29: 경력합계 | R29: =SUM(R24:T28) -> 0
B30: 가 족 사 항 | E30: 성 명 | H30: 관 계 | J30: 생년월일 | M30: 직 업 | P30: 학력 | S30: 비고
E31: 김희진 | H31: 처 | J31: 29697
E32: 김채율 | H32: 자녀 | J32: 41002
E33: 김채아 | H33: 자녀 | J33: 42488
E34: 김시후 | H34: 자녀 | J34: 43941

Sheet 강종태
B1: 직원 인사 기록 카드
B2: =TODAY() -> 46113
B3: 입 사 일 자 | E3: 37865 | L3: 퇴 사 일 자 | W3: 소속본부 및 팀 | AA3: 경영총괄실
B5: 이 름 | E5: 강 종 태 | L5: 종 교 | N5: 불교 | R5: 사 진
B6: 생 년 월 일 | E6: 27844 | L6: 나 이 | N6: =DATEDIF(E6,TODAY(),"y") -> 50
B7: 주민등록번호 | E7: 760405-1011314 | L7: 근속연수 | N7: =(B2-E3)/365 -> 22.59726
B8: 현 주 소 | E8: 경기도 의왕시 | K8: 포일세거리로 73 401동 201호
B9: 거 주 지 | E9: 경기 의왕시 포일세거리로 73 401동 201호
B10: 전 화 번 호 | E10: 031-211-6167 (011-9030-6167) | M10: 결혼유무
B11: 자 격 사 항 | E11: 종 류 | J11: 취 득 일 | O11: 특 기
E12: 수학영재지도자과정 수료 | J12: 38884
E13: 커뮤니케이션역량과정 수료 | J13: 41097
E14: 17기벤처최고경영자과정 | J14: 42353
B15: 병 력 사 항
E16: 기 간 | G16: 1998. 8. ~ 2000. 2. | N16: 최종 계급 | Q16: 상병
E17: 군 별 | G17: 공군 | N17: 병 과 | Q17: 항공기체정비
B18: 학 력 | E18: 기 간 | I18: 학교 및 전공 | N18: 졸업년월 | Q18: 최종학력
E19: 1992. 3. ~ 1995. 2. | I19: 수성고등학교 | N19: 1995. 2. | Q19: 대졸
E20: 1996. 3. ~ 2003. 8. | I20: 서울대 | L20: 기계항공공학부 | N20: 2003. 8.
B23: 경 력 | E23: 재 직 기 간 | K23: 근 무 부 서 | N23: 직 장 명 | P23: 직 위 | R23: 근 무 년 수
P29: 경력합계
B30: 가 족 사 항 | E30: 성 명 | H30: 관 계 | J30: 생년월일 | M30: 직 업 | P30: 학력 | S30: 비고
E31: 강용성 | H31: 父 | J31: 1948. 1. 14.
E32: 최기순 | H32: 母 | J32: 1951. 12. 16.
E33: 오선희 | H33: 처 | J33: 29875
E34: 강다은 | H34: 자녀 | J34: 44201

Sheet 이상훈
B1: 직원 인사 기록 카드
B2: =TODAY() -> 46113
B3: 입 사 일 자 | E3: 39661 | L3: 퇴 사 일 자 | W3: 소속본부 및 팀 | AA3: 출판사업본부
B5: 이 름 | E5: 이 상 훈 | L5: 종 교 | R5: 사 진
B6: 생 년 월 일 | E6: 26671 | L6: 나 이 | N6: =DATEDIF(E6,TODAY(),"y") -> 53
B7: 주민등록번호 | E7: 730107-1006722 | L7: 근속연수 | N7: =(B2-E3)/365 -> 17.676712
B8: 현 주 소 | E8: 경기도 고양시 덕양구 | L8: 고양동 푸른마을 101동 2102호
B9: 거 주 지 | E9: 상 동
B10: 전 화 번 호 | E10: 011 - 9021 - 9315 | M10: 결혼유무
B11: 자 격 사 항 | E11: 종 류 | J11: 취 득 일 | O11: 특 기
E12: 운전면허 보통 1종
B15: 병 력 사 항
E16: 기 간 | G16: 1995/01 ~ 1997/03 | N16: 최종 계급 | Q16: 병장
E17: 군 별 | G17: 육군 | N17: 병 과 | Q17: 전투공병
B18: 학 력 | E18: 기 간 | I18: 학교 및 전공 | N18: 졸업년월 | Q18: 최종학력
E19: 1987 ~ 1990 | I19: 서울 인창고등학교 | N19: 1990.02 | Q19: 대졸
E20: 1994 ~ 2001 | I20: 명지대학교 | K20: 행정학(법학) | N20: 2001.02
B23: 경 력 | E23: 재 직 기 간 | K23: 근 무 부 서 | N23: 직 장 명 | P23: 직 위 | R23: 근 무 년 수
E24: 33298 | H24: 34000 | K24: 경영관리 | N24: 흥진출판사 | P24: 사원 | R24: =(H24-E24)/365 -> 1.9232877
E25: 36861 | H25: 38671 | K25: 홍보(영업) | N25: 중앙교육 입시연구원 | P25: 과장 | R25: =(H25-E25)/365 -> 4.9589041
E26: 38672 | H26: 39005 | K26: 영업 | N26: 도서총판 백신도서 | P26: 부장 | R26: =(H26-E26)/365 -> 0.91232877
E27: 39006 | H27: 39629 | K27: 경영기획 | N27: 학천미디어 | P27: 과장 | R27: =(H27-E27)/365 -> 1.7068493
P29: 경력합계 | R29: =SUM(R24:T28) -> 9.5013699
B30: 가 족 사 항 | E30: 성 명 | H30: 관 계 | J30: 생년월일 | M30: 직 업 | P30: 학력 | S30: 비고
E31: 이상훈 | H31: 본인 | J31: 1973.01.07 | M31: 회사원 | P31: 대졸
E32: 장학실 | H32: 처 | J32: 1971.09.13 | M32: 주부 | P32: 대졸
E33: 이진영 | H33: 자 | J33: 2003.12.29 | M33: 초등학생 | P33: 초등학교 재

Sheet 전연진
B1: 직원 인사 기록 카드
B2: =TODAY() -> 46113
B3: 입 사 일 자 | E3: 39699 | L3: 퇴 사 일 자 | W3: 소속본부 및 팀 | AA3: 연구소 | AE3: 개발팀
B5: 이 름 | E5: 전 연 진 | L5: 종 교 | N5: 無 | R5: 사 진
B6: 생 년 월 일 | E6: 29299 | L6: 나 이 | N6: =DATEDIF(E6,TODAY(),"y") -> 46
B7: 주민등록번호 | E7: 800319-2009518 | L7: 근속연수 | N7: =(B2-E3)/365 -> 17.572603
B8: 현 주 소 | E8: 경기도 부천시 | L8: 옥길로 55 709동 1402호
B9: 거 주 지 | E9: 경기도 부천시 옥길로 55 709동 1402호
B10: 전 화 번 호 | E10: 010-4183-0319 | M10: 결혼유무
B11: 자 격 사 항 | E11: 종 류 | J11: 취 득 일 | O11: 특 기
E12: 자동차운전면허 1종보통 | J12: 2003.01.11
E13: 워드프로세서 | J13: 2005.09.08
E14: 대기환경기사 | J14: 2005.09.11
B15: 병 력 사 항
E16: 기 간 | N16: 최종 계급
E17: 군 별 | N17: 병 과
B18: 학 력 | E18: 기 간 | I18: 학교 및 전공 | N18: 졸업년월 | Q18: 최종학력
E19: 1999.03 ~ 2003.02 | I19: 강원대학교 전자계산환경과학과군 | N19: 2003.02 | Q19: 석사
E20: 2008.09 ~ 2011.02 | I20: 건국대 교육대학원 | L20: 영재교육전공 | N20: 2011.02
B23: 경 력 | E23: 재 직 기 간 | K23: 근 무 부 서 | N23: 직 장 명 | P23: 직 위 | R23: 근 무 년 수
E24: 37622 | H24: 38534 | N24: 와이즈만영재교육원 | P24: 팀장 | R24: =(H24-E24)/365 -> 2.4986301
E25: 38565 | H25: 38687 | K25: 초등개발 | N25: (주)에듀왕 | P25: 사원 | R25: =(H25-E25)/365 -> 0.33424658
E26: 38687 | H26: 39539 | K26: 기획조정본부 | N26: ㈜이루넷 | P26: 사원 | R26: =(H26-E26)/365 -> 2.3342466
E27: 39539 | H27: 39692 | N27: 폴라사이언스 | P27: 대리 | R27: =(H27-E27)/365 -> 0.41917808
R28: =(H28-E28)/365 -> 0
P29: 경력합계 | R29: =SUM(R24:T28) -> 5.5863014
B30: 가 족 사 항 | E30: 성 명 | H30: 관 계 | J30: 생년월일 | M30: 직 업 | P30: 학력 | S30: 비고
E31: 차승규 | H31: 남편 | J31: 29081 | M31: 회사원
E32: 차민우 | H32: 자녀 | J32: 41009
E33: 차유승 | H33: 자녀

Sheet 유상욱
B1: 직원 인사 기록 카드
B2: =TODAY() -> 46113
B3: 입 사 일 자 | E3: 39734 | L3: 퇴 사 일 자 | W3: 소속본부 및 팀 | AA3: 연구소 | AE3: 스마트학습팀
B5: 이 름 | E5: 류 상 욱 | L5: 종 교 | N5: 무교 | R5: 사 진
B6: 생 년 월 일 | E6: 28765 | L6: 나 이 | N6: =DATEDIF(E6,TODAY(),"y") -> 47
B7: 주민등록번호 | E7: 781002-1030311 | L7: 근속연수 | N7: =(B2-E3)/365 -> 17.476712
B8: 현 주 소 | E8: 경기도 하남시 | K8: 감일백제로 65 1202동 2005호
B9: 거 주 지 | E9: 경기 하남시 감일백제로 65 1202동 2005호
B10: 전 화 번 호 | E10: 010-6487-7217 | M10: 결혼유무
B11: 자 격 사 항 | E11: 종 류 | J11: 취 득 일 | O11: 특 기
E12: 정보처리기사
E13: 무선통신기사
E14: 운전면허1종보통
B15: 병 력 사 항
E16: 기 간 | G16: 2004~2006 | N16: 최종 계급 | Q16: 병장
E17: 군 별 | G17: 육군 | N17: 병 과 | Q17: 위성통신
B18: 학 력 | E18: 기 간 | I18: 학교 및 전공 | N18: 졸업년월 | Q18: 최종학력
E19: ~1997 | I19: 인헌고등학교 | N19: 1997 | Q19: 대졸
E20: ~2002 | I20: 국민대학교 | L20: 전자공학 | N20: 2002
B23: 경 력 | E23: 재 직 기 간 | K23: 근 무 부 서 | N23: 직 장 명 | P23: 직 위 | R23: 근 무 년 수
R24: =(H24-E24)/365 -> 0
R25: =(H25-E25)/365 -> 0
R26: =(H26-E26)/365 -> 0
R27: =(H27-E27)/365 -> 0
R28: =(H28-E28)/365 -> 0
P29: 경력합계 | R29: =SUM(R24:T28) -> 0
B30: 가 족 사 항 | E30: 성 명 | H30: 관 계 | J30: 생년월일 | M30: 직 업 | P30: 학력 | S30: 비고
E31: 유승길 | H31: 부 | J31: 1948.3.3 | M31: 운수업 | P31: 고졸
E32: 김경애 | H32: 모 | J32: 1954.6.2 | M32: 주부 | P32: 고졸
E33: 유지식 | H33: 형 | J33: 1977.4.24 | M33: 직장인 | P33: 대졸

Sheet 송재완
B1: 직원 인사 기록 카드
B2: =TODAY() -> 46113
B3: 입 사 일 자 | E3: 39762 | L3: 퇴 사 일 자 | W3: 소속본부 및 팀 | AA3: 출판사업본부 | AE3: 출판영업팀
B5: 이 름 | E5: 송 재 완 | L5: 종 교 | R5: 사 진
B6: 생 년 월 일 | E6: 28335 | L6: 나 이 | N6: =DATEDIF(E6,TODAY(),"y") -> 48
B7: 주민등록번호 | E7: 770729-1520311 | L7: 근속연수 | N7: =(B2-E3)/365 -> 17.4
B8: 현 주 소 | E8: 경기도 수원시 장안구 | L8: 정자동 연꽃마을 424동 801호
B9: 거 주 지 | E9: 경기도 수원시 장안구 정자동 연꽃마을 424동 801호
B10: 전 화 번 호 | E10: 010-4715-1977 | M10: 결혼유무
B11: 자 격 사 항 | E11: 종 류 | J11: 취 득 일 | O11: 특 기
B15: 병 력 사 항
E16: 기 간 | N16: 최종 계급 | Q16: 병장
E17: 군 별 | G17: 육군 | N17: 병 과
B18: 학 력 | E18: 기 간 | I18: 학교 및 전공 | N18: 졸업년월 | Q18: 최종학력
E19: 1993 ~ 1996 | I19: 흥진고등학교 | N19: 1996.02 | Q19: 대졸
E20: 1996 ~ 2001 | I20: 호원대학교 | K20: 관광경영학 | N20: 2001.02
B23: 경 력 | E23: 재 직 기 간 | K23: 근 무 부 서 | N23: 직 장 명 | P23: 직 위 | R23: 근 무 년 수
E24: 37561 | H24: 39508 | K24: 영업부 | N24: 시공사 | P24: 대리 | R24: =(H24-E24)/365 -> 5.3342466
R25: =(H25-E25)/365 -> 0
R26: =(H26-E26)/365 -> 0
R27: =(H27-E27)/365 -> 0
P29: 경력합계 | R29: =SUM(R24:T28) -> 5.3342466
B30: 가 족 사 항 | E30: 성 명 | H30: 관 계 | J30: 생년월일 | M30: 직 업 | P30: 학력 | S30: 비고
E31: 박 수 현 | H31: 처 | J31: 28439
E32: 송 지 민 | H32: 자 | J32: 38379

Sheet 양현미
B1: 직원 인사 기록 카드
B2: =TODAY() -> 46113
B3: 입 사 일 자 | E3: 40210 | L3: 퇴 사 일 자 | W3: 소속본부 및 팀 | AA3: 학원사업본부 | AE3: 직영교육팀
B5: 이 름 | E5: 양 현 미 | L5: 종 교 | N5: 無 | R5: 사 진
B6: 생 년 월 일 | E6: 28064 | L6: 나 이 | N6: =DATEDIF(E6,TODAY(),"y") -> 49
B7: 주민등록번호 | E7: 761031-2024422 | L7: 근속연수 | N7: =(B2-E3)/365 -> 16.172603
B8: 현 주 소 | E8: 서울시 성북구 | L8: 종암동 10-54번지 201호
B9: 거 주 지 | E9: 서울시 성북구 종암동 10-54번지 201호
B10: 전 화 번 호 | M10: 결혼유무
B11: 자 격 사 항 | E11: 종 류 | J11: 취 득 일 | O11: 특 기
E12: 이러닝지도사2급 | J12: 2008.4.30
B15: 병 력 사 항
E16: 기 간 | N16: 최종 계급
E17: 군 별 | N17: 병 과
B18: 학 력 | E18: 기 간 | I18: 학교 및 전공 | N18: 졸업년월 | Q18: 최종학력
E19: 1992.3~1995.2 | I19: 한성여자고등학교 졸업 | N19: 1995.2 | Q19: 대졸
E20: 1995.3~2000.2 | I20: 상명대학교 | L20: 지리학 | N20: 2000.2
B23: 경 력 | E23: 재 직 기 간 | K23: 근 무 부 서 | N23: 직 장 명 | P23: 직 위 | R23: 근 무 년 수
E24: 36708 | H24: 37135 | K24: 리테일사업팀 | N24: 한미은행 | P24: 행원 | R24: =(H24-E24)/365 -> 1.169863
E25: 37408 | H25: 38078 | K25: 학습지사업부 | N25: ㈜세스넷 | P25: 사원 | R25: =(H25-E25)/365 -> 1.8356164
E26: 38078 | H26: 39326 | K26: 교육홍보팀 | N26: ㈜푸른영어 | P26: 대리 | R26: =(H26-E26)/365 -> 3.4191781
E27: 39539 | H27: 39722 | K27: 교육팀 | N27: ㈜위드에프피 (현.웅진패스원) | P27: 과장 | R27: =(H27-E27)/365 -> 0.50136986
E28: 39873 | H28: 40148 | K28: 이러닝사업부 | N28: ㈜영교 | P28: 사원 | R28: =(H28-E28)/365 -> 0.75342466
P29: 경력합계 | R29: =SUM(R24:T28) -> 7.6794521
B30: 가 족 사 항 | E30: 성 명 | H30: 관 계 | J30: 생년월일 | M30: 직 업 | P30: 학력 | S30: 비고
E31: 양득승 | H31: 부 | J31: 1948.5.1 | M31: 퇴직 | P31: 대졸
E32: 조인상 | H32: 모 | J32: 1593.12.2 | M32: 사업 | P32: 대졸
E33: 양운상 | H33: 오빠 | J33: 1974.10.6 | M33: 사업 | P33: 대학원졸

Sheet 심종주
B1: 직원 인사 기록 카드
B2: =TODAY() -> 46113
B3: 입 사 일 자 | E3: 40225 | L3: 퇴 사 일 자 | W3: 소속본부 및 팀 | AA3: 경영총괄실 | AE3: 경영지원팀
B5: 이 름 | E5: 심 종 주 | L5: 종 교 | N5: 무 | R5: 사 진
B6: 생 년 월 일 | E6: 30447 | L6: 나 이 | N6: =DATEDIF(E6,TODAY(),"y") -> 42
B7: 주민등록번호 | E7: 830511-1012516 | L7: 근속연수 | N7: =(B2-E3)/365 -> 16.131507
B8: 현 주 소 | E8: 경기도 파주시 | K8: 청암로28 819동 801호
B9: 거 주 지 | E9: 경기도 파주시 청암로28 819동801ㅗㅓ
B10: 전 화 번 호 | E10: 010-3026-0047 | M10: 결혼유무
B11: 자 격 사 항 | E11: 종 류 | J11: 취 득 일 | O11: 특 기
E12: 노무관리 이슈/트렌드 수료 | J12: 44585
E13: 근로기준법 실무 수료 | J13: 41687
E14: 원가절감 분석 수료 | J14: 41143
B15: 병 력 사 항
E16: 기 간 | G16: 2003.06 ~ 2005.08 | N16: 최종 계급
E17: 군 별 | G17: 공익근무 | N17: 병 과
B18: 학 력 | E18: 기 간 | I18: 학교 및 전공 | N18: 졸업년월 | Q18: 최종학력
E19: 2009.08 졸업 | I19: 한성대학교 | L19: 경영학과 | Q19: 대졸
B23: 경 력 | E23: 재 직 기 간 | K23: 근 무 부 서 | N23: 직 장 명 | P23: 직 위 | R23: 근 무 년 수
E24: 38588 | H24: 38952 | K24: 일산지점 총무과 | N24: 농협중앙회 | P24: 사원 | R24: =(H24-E24)/365 -> 0.99726027
R25: =(H25-E25)/365 -> 0
R26: =(H26-E26)/365 -> 0
R27: =(H27-E27)/365 -> 0
R28: =(H28-E28)/365 -> 0
P29: 경력합계 | R29: =SUM(R24:T28) -> 0.99726027
B30: 가 족 사 항 | E30: 성 명 | H30: 관 계 | J30: 생년월일 | M30: 직 업 | P30: 학력 | S30: 비고
E31: 강지민 | H31: 처 | J31: 29366
E32: 심재희 | H32: 자녀 | J32: 41215
E33: 심찬희 | H33: 자녀 | J33: 42587

Sheet 박민정
B1: 직원 인사 기록 카드
B2: =TODAY() -> 46113
B3: 입 사 일 자 | E3: 40525 | L3: 퇴 사 일 자 | W3: 소속본부 및 팀 | AA3: 경영총괄실 | AE3: 경영지원팀
B5: 이 름 | E5: 박 민 정 | L5: 종 교 | N5: 무교 | R5: 사 진
B6: 생 년 월 일 | E6: 31836 | L6: 나 이 | N6: =DATEDIF(E6,TODAY(),"y") -> 39
B7: 주민등록번호 | E7: 870228-2382119 | L7: 근속연수 | N7: =(B2-E3)/365 -> 15.309589
B8: 현 주 소 | E8: 충북 보은군 보은읍 | K8: 삼산리 122-4
B9: 거 주 지 | E9: 서울시 중랑구 면목동 300-14
B10: 전 화 번 호 | E10: 010-7444-1004 | M10: 결혼유무
B11: 자 격 사 항 | E11: 종 류 | J11: 취 득 일 | O11: 특 기
E12: 사무자동화산업기사 | J12: 2010.08.13
E13: 워드프로세서 1급 | J13: 2009.09.04
B15: 병 력 사 항
E16: 기 간 | N16: 최종 계급
E17: 군 별 | N17: 병 과
B18: 학 력 | E18: 기 간 | I18: 학교 및 전공 | N18: 졸업년월 | Q18: 최종학력
E19: 2007.03 | I19: 한남대학교 | L19: 수학과 | N19: 2011.02 | Q19: 대졸
B23: 경 력 | E23: 재 직 기 간 | K23: 근 무 부 서 | N23: 직 장 명 | P23: 직 위 | R23: 근 무 년 수
R24: =(H24-E24)/365 -> 0
R25: =(H25-E25)/365 -> 0
R26: =(H26-E26)/365 -> 0
R27: =(H27-E27)/365 -> 0
R28: =(H28-E28)/365 -> 0
P29: 경력합계 | R29: =SUM(R24:T28) -> 0
B30: 가 족 사 항 | E30: 성 명 | H30: 관 계 | J30: 생년월일 | M30: 직 업 | P30: 학력 | S30: 비고
E31: 박세일 | H31: 부 | J31: 1960.05.20 | P31: 대졸
E32: 길정자 | H32: 모 | J32: 1963.02.28 | P32: 초대졸
E33: 박석진 | H33: 제 | J33: 1989.02.13 | P33: 대학 재학

Sheet 최철호
B1: 직원 인사 기록 카드
B2: =TODAY() -> 46113
B3: 입 사 일 자 | E3: 40756 | L3: 퇴 사 일 자 | W3: 소속본부 및 팀 | AA3: 출판사업본부 | AE3: 출판영업팀
B5: 이 름 | E5: 최 철 호 | L5: 종 교 | R5: 사 진
B6: 생 년 월 일 | E6: 23520 | L6: 나 이 | N6: =DATEDIF(E6,TODAY(),"y") -> 61
B7: 주민등록번호 | E7: 640523-1101216 | L7: 근속연수 | N7: =(B2-E3)/365 -> 14.676712
B8: 현 주 소 | E8: 경기도 고양시 일산동구 | K8: 고봉로278번길 17, 207동 2401호(이편한세상아파트)
B9: 거 주 지 | E9: 경기도 고양시 일산동구 고봉로278번길 17, 207동 2401호(이편한세상아파트)
B10: 전 화 번 호 | E10: 010-8314-0775 | M10: 결혼유무
B11: 자 격 사 항 | E11: 종 류 | J11: 취 득 일 | O11: 특 기
B15: 병 력 사 항
E16: 기 간 | N16: 최종 계급
E17: 군 별 | N17: 병 과
B18: 학 력 | E18: 기 간 | I18: 학교 및 전공 | N18: 졸업년월 | Q18: 최종학력
E19: 1983.03 ~ 1993.08 | I19: 서울대학교 | L19: 수학과 | N19: 1993.08 | Q19: 대졸
B23: 경 력 | E23: 재 직 기 간 | K23: 근 무 부 서 | N23: 직 장 명 | P23: 직 위 | R23: 근 무 년 수
E24: 36586 | H24: 40237 | N24: ㈜제사교육 | P24: 부사장 | R24: =(H24-E24)/365 -> 10.00274
E25: 40238 | H25: 40755 | N25: ㈜티스터디 | P25: 이사 | R25: =(H25-E25)/365 -> 1.4164384
R26: =(H26-E26)/365 -> 0
P29: 경력합계 | R29: =SUM(R24:T28) -> 11.419178
B30: 가 족 사 항 | E30: 성 명 | H30: 관 계 | J30: 생년월일 | M30: 직 업 | P30: 학력 | S30: 비고
E31: 장미련 | H31: 배우자 | J31: 23563 | M31: 주부
E32: 최혜우 | H32: 녀 | J32: 34314 | P32: 학생
E33: 최은우 | H33: 자 | J33: 34843 | P33: 학생

Sheet 김진형
B1: 직원 인사 기록 카드
B2: =TODAY() -> 46113
B3: 입 사 일 자 | E3: 41554 | L3: 퇴 사 일 자 | W3: 소속본부 및 팀 | AA3: 학원사업본부 | AE3: 가맹사업팀
B5: 이 름 | E5: 김 진 형 | L5: 종 교 | R5: 사 진
B6: 생 년 월 일 | E6: 30594 | L6: 나 이 | N6: =DATEDIF(E6,TODAY(),"y") -> 42
B7: 주민등록번호 | E7: 831005-1051713 | L7: 근속연수 | N7: =(B2-E3)/365 -> 12.490411
B8: 현 주 소 | E8: 서울특별시 은평구 진관동 22 | L8: 은평뉴타운 구파발909-402
B9: 거 주 지 | E9: 상 동
B10: 전 화 번 호 | E10: 010-8888-3677 | M10: 결혼유무
B11: 자 격 사 항 | E11: 종 류 | J11: 취 득 일 | O11: 특 기
B15: 병 력 사 항
E16: 기 간 | G16: 2009.11~2012.10 | N16: 최종 계급 | Q16: 중위
E17: 군 별 | N17: 병 과
B18: 학 력 | E18: 기 간 | I18: 학교 및 전공 | N18: 졸업년월 | Q18: 최종학력
E19: 2002.02 졸업 | I19: 서라벌 고등학교 | N19: 37315 | Q19: 대졸
E20: 2003.03~2008.01 | I20: TSING HUA UNI. | K20: 중어중문 | N20: 39661
B23: 경 력 | E23: 재 직 기 간 | K23: 근 무 부 서 | N23: 직 장 명 | P23: 직 위 | R23: 근 무 년 수
R24: =(H24-E24)/365 -> 0
R25: =(H25-E25)/365 -> 0
R26: =(H26-E26)/365 -> 0
R27: =(H27-E27)/365 -> 0
P29: 경력합계 | R29: =SUM(R24:T28) -> 0
B30: 가 족 사 항 | E30: 성 명 | H30: 관 계 | J30: 생년월일 | M30: 직 업 | P30: 학력 | S30: 비고
E31: 김남규 | H31: 부
E32: 박정금 | H32: 모

Sheet 김숙희
B1: 직원 인사 기록 카드
B2: =TODAY() -> 46113
B3: 입 사 일 자 | E3: 41699 | L3: 퇴 사 일 자 | W3: 소속본부 및 팀 | AA3: 연구소 | AE3: 개발팀
B5: 이 름 | E5: 김 숙 희 | L5: 종 교 | R5: 사 진
B6: 생 년 월 일 | E6: 32385 | L6: 나 이 | N6: =DATEDIF(E6,TODAY(),"y") -> 37
B7: 주민등록번호 | E7: 880830-2055025 | L7: 근속연수 | N7: =(B2-E3)/365 -> 12.093151
B8: 현 주 소 | E8: 서울 송파구 오륜동 | L8: 올림픽선수촌아파트 303-2104
B9: 거 주 지 | E9: 상 동
B10: 전 화 번 호 | E10: 010-9093-6829 | M10: 결혼유무
B11: 자 격 사 항 | E11: 종 류 | J11: 취 득 일 | O11: 특 기
E12: 컴퓨터활용능력2급 | J12: 2011.07.29
E13: MOSmaster 2007 | J13: 2010.07.17
E14: 한자자격검정 2급 | J14: 2011.03.24
B15: 병 력 사 항
E16: 기 간 | N16: 최종 계급
E17: 군 별 | N17: 병 과
B18: 학 력 | E18: 기 간 | I18: 학교 및 전공 | N18: 졸업년월 | Q18: 최종학력
E19: 2004.03~2007.02 | I19: 창덕여자고등학교 이과 | N19: 39141 | Q19: 학사
E20: 2007.03~2012.02 | I20: 서울여자대학교 | K20: 수학과 | N20: 40967
B23: 경 력 | E23: 재 직 기 간 | K23: 근 무 부 서 | N23: 직 장 명 | P23: 직 위 | R23: 근 무 년 수
R24: =(H24-E24)/365 -> 0
R25: =(H25-E25)/365 -> 0
P29: 경력합계 | R29: =SUM(R24:T28) -> 0
B30: 가 족 사 항 | E30: 성 명 | H30: 관 계 | J30: 생년월일 | M30: 직 업 | P30: 학력 | S30: 비고
E31: 김홍기 | H31: 부 | J31: 1961
E32: 정정임 | H32: 모 | J32: 1964
E33: 김애란 | H33: 언니 | J33: 1986
E34: 김지연 | H34: 동생 | J34: 1991

Sheet 김소라
B1: 직원 인사 기록 카드
B2: =TODAY() -> 46113
B3: 입 사 일 자 | E3: 41722 | L3: 퇴 사 일 자 | W3: 소속본부 및 팀 | AA3: 연구소 | AE3: 개발팀
B5: 이 름 | E5: 김소라 | L5: 종 교 | R5: 사 진
B6: 생 년 월 일 | E6: 32093 | L6: 나 이 | N6: =DATEDIF(E6,TODAY(),"y") -> 38
B7: 주민등록번호 | E7: 871113-2320914 | L7: 근속연수 | N7: =(B2-E3)/365 -> 12.030137
B8: 현 주 소 | E8: 서울시 중랑구 | L8: 면목동 31-32 301호
B9: 거 주 지 | E9: 서울시 중랑구 면목동 31-32 301호
B10: 전 화 번 호 | E10: 010-4455-7159 | M10: 결혼유무
B11: 자 격 사 항 | E11: 종 류 | J11: 취 득 일 | O11: 특 기
E12: MOS Master 2003 | J12: 39904
E13: 사무자동화산업기사 | J13: 40695
E14: 전자출판기능사 | J14: 41061
B15: 병 력 사 항
E16: 기 간 | N16: 최종 계급
E17: 군 별 | N17: 병 과
B18: 학 력 | E18: 기 간 | I18: 학교 및 전공 | N18: 졸업년월 | Q18: 최종학력
I19: 홍천여자고등학교 | N19: 38776 | Q19: 학사
I20: 강원대학교 | K20: 생명공학과 | N20: 40237
B23: 경 력 | E23: 재 직 기 간 | K23: 근 무 부 서 | N23: 직 장 명 | P23: 직 위 | R23: 근 무 년 수
E24: 41122 | H24: 41698 | K24: 디자인팀 | N24: 세광음악출판사 | R24: =(H24-E24)/365 -> 1.5780822
R25: =(H25-E25)/365 -> 0
R26: =(H26-E26)/365 -> 0
R27: =(H27-E27)/365 -> 0
R28: =(H28-E28)/365 -> 0
R29: =(H29-E29)/365 -> 0 | U29: =R24+R25+R26+R27+R28+R29 -> 1.5780822
B30: 가 족 사 항 | E30: 성 명 | H30: 관 계 | J30: 생년월일 | M30: 직 업 | P30: 학력 | S30: 비고
E31: 문영진 | H31: 배우자 | J31: 30326 | S31: 010-2072-3703
E32: 문동욱 | H32: 자녀 | J32: 43108

Sheet 오우림
B1: 직원 인사 기록 카드
B2: =TODAY() -> 46113
B3: 입 사 일 자 | E3: 42309 | L3: 퇴 사 일 자 | W3: 소속본부 및 팀 | AA3: 학원사업본부 | AE3: 가맹영업팀
B5: 이 름 | E5: 오 우 림 | L5: 종 교 | R5: 사 진
B6: 생 년 월 일 | E6: 32681 | L6: 나 이 | N6: =DATEDIF(E6,TODAY(),"y") -> 36
B7: 주민등록번호 | E7: 890622-1243412 | L7: 근속연수 | N7: =(B2-E3)/365 -> 10.421918
B8: 현 주 소 | E8: 경기도 수원시 팔당구 | L8: 고등로 15 143동 1607호
B9: 거 주 지 | E9: 경기도 수원시 팔당구 고등로 15 143동 1607호
B10: 전 화 번 호 | E10: 010-9504-6676 | M10: 결혼유무
B11: 자 격 사 항 | E11: 종 류 | J11: 취 득 일 | O11: 특 기
B15: 병 력 사 항
E16: 기 간 | G16: 2010년4월~2012년1월 | N16: 최종 계급 | Q16: 병장
E17: 군 별 | N17: 병 과
B18: 학 력 | E18: 기 간 | I18: 학교 및 전공 | N18: 졸업년월 | Q18: 최종학력
E19: 39506 | I19: 조종고등학교 | N19: 39506 | Q19: 대졸
E20: 2008-03~2014-02 | I20: 건국대학교 | K20: 생명공학 | N20: 41698
B23: 경 력 | E23: 재 직 기 간 | K23: 근 무 부 서 | N23: 직 장 명 | P23: 직 위 | R23: 근 무 년 수
P29: 경력합계 | R29: =SUM(R24:T28) -> 0
B30: 가 족 사 항 | E30: 성 명 | H30: 관 계 | J30: 생년월일 | M30: 직 업 | P30: 학력 | S30: 비고
E31: 오성환 | H31: 부
E32: 최영해 | H32: 모
E33: 조성아 | H33: 배우자
E34: 오지은 | H34: 자녀
E35: 오윤재 | H35: 자녀

Sheet 박미영
B1: 직원 인사 기록 카드
B2: =TODAY() -> 46113
B3: 입 사 일 자 | E3: 42814 | L3: 퇴 사 일 자 | W3: 소속본부 및 팀 | AA3: 연구소 | AE3: IT디자인팀
B5: 이 름 | E5: 박 미 영 | L5: 종 교 | R5: 사 진
B6: 생 년 월 일 | E6: 27098 | L6: 나 이 | N6: =DATEDIF(E6,TODAY(),"y") -> 52
B7: 주민등록번호 | E7: 740310-2144119 | L7: 근속연수 | N7: =(B2-E3)/365 -> 9.0383562
B8: 현 주 소 | E8: 서울특별시 송파구 | L8: 문정동 652-4 810호
B9: 거 주 지 | E9: 서울특별시 송파구 문정동 652-4 810호
B10: 전 화 번 호 | E10: 010-5161-2536 | M10: 결혼유무
B11: 자 격 사 항 | E11: 종 류 | J11: 취 득 일 | O11: 특 기
B15: 병 력 사 항
E16: 기 간 | N16: 최종 계급
E17: 군 별 | N17: 병 과
B18: 학 력 | E18: 기 간 | I18: 학교 및 전공 | N18: 졸업년월 | Q18: 최종학력
Q19: 대졸
E20: 1998-03~2000-02 | I20: 인천대학교 | K20: 영어과 | N20: 36557
B23: 경 력 | E23: 재 직 기 간 | K23: 근 무 부 서 | N23: 직 장 명 | P23: 직 위 | R23: 근 무 년 수
N24: 푸른날개(단행본)
N25: ㈜삼성비엔씨
N26: ㈜기호일보
P29: 경력합계 | R29: 10
B30: 가 족 사 항 | E30: 성 명 | H30: 관 계 | J30: 생년월일 | M30: 직 업 | P30: 학력 | S30: 비고
E31: 신영희 | H31: 모 | J31: 16736

Sheet 이동희
B1: 직원 인사 기록 카드
B2: =TODAY() -> 46113
B3: 입 사 일 자 | E3: 42917 | L3: 퇴 사 일 자 | W3: 소속본부 및 팀 | AA3: 연구소 | AE3: IT디자인팀
B5: 이 름 | E5: 이 동 희 | L5: 종 교 | R5: 사 진
B6: 생 년 월 일 | E6: 33525 | L6: 나 이 | N6: =DATEDIF(E6,TODAY(),"y") -> 34
B7: 주민등록번호 | E7: 911014-2013317 | L7: 근속연수 | N7: =(B2-E3)/365 -> 8.7561644
B8: 현 주 소 | E8: 서울시 도봉구 | K8: 시루봉로25길 30(도봉동)
B9: 거 주 지 | E9: 서울특별시 도봉구 시루봉로25길 30 (도봉동)
B10: 전 화 번 호 | E10: 010-2589-9400 | M10: 결혼유무
B11: 자 격 사 항 | E11: 종 류 | J11: 취 득 일 | O11: 특 기
B15: 병 력 사 항
E16: 기 간 | N16: 최종 계급
E17: 군 별 | N17: 병 과
B18: 학 력 | E18: 기 간 | I18: 학교 및 전공 | N18: 졸업년월 | Q18: 최종학력
E19: 2012-03~2017-02 | I19: 동덕여대 | L19: 국문학 | N19: 2017.02 | Q19: 대졸
E20: 2007-03~2010-02 | I20: 도봉고등학교 | L20: 인문 | N20: 2010.02
B23: 경 력 | E23: 재 직 기 간 | K23: 근 무 부 서 | N23: 직 장 명 | P23: 직 위 | R23: 근 무 년 수
E24: 40969 | H24: 41698 | K24: 영화제홍보 | N24: 교외동아리 | R24: =(H24-E24)/365 -> 1.9972603
E25: 41001 | H25: 41698 | K25: 영화제 홍보 | N25: 교내동아리 | R25: =(H25-E25)/365 -> 1.909589
E26: 41334 | H26: 41698 | K26: 밴드공연홍보 | N26: 교내동아리 | R26: =(H26-E26)/365 -> 0.99726027
E27: 42065 | H27: 42185 | K27: 마케팅 | N27: 청춘자생캠페인 | R27: =(H27-E27)/365 -> 0.32876712
E28: 42278 | H28: 42460 | K28: 아르바이트 | R28: =(H28-E28)/365 -> 0.49863014
E29: 42705 | H29: 42794 | K29: 빅데이터 소셜마케팅 양성과정 | R29: =(H29-E29)/365 -> 0.24383562
P30: 경력합계 | R30: =SUM(R24:T29) -> 5.9753425
B31: 가 족 사 항 | E31: 성 명 | H31: 관 계 | J31: 생년월일 | M31: 직 업 | P31: 학력 | S31: 비고
E32: 이길수 | H32: 부 | J32: 22077
E33: 이찬희 | H33: 모 | J33: 22635
E34: 이동현 | H34: 형제 | J34: 32408

Sheet 최준석
B1: 직원 인사 기록 카드
B2: =TODAY() -> 46113
B3: 입 사 일 자 | E3: 43031 | L3: 퇴 사 일 자 | W3: 소속본부 및 팀 | AA3: 경영총괄실 | AE3: 물류팀
B5: 이 름 | E5: 최 준 석 | L5: 종 교 | R5: 사 진
B6: 생 년 월 일 | E6: 30346 | L6: 나 이 | N6: =DATEDIF(E6,TODAY(),"y") -> 43
B7: 주민등록번호 | E7: 830130-1178327 | L7: 근속연수 | N7: =(B2-E3)/365 -> 8.4438356
B8: 현 주 소 | E8: 경기도 김포시 | K8: 봉화로59-17 농장마을 신안아파트 105-702
B9: 거 주 지 | E9: 경기도 김포시 봉화로59-17 농장마을 신안아파트 105-702
B10: 전 화 번 호 | E10: 010-7189-0243 | M10: 결혼유무
B11: 자 격 사 항 | E11: 종 류 | J11: 취 득 일 | O11: 특 기
E12: 건설기계조종사면허 | J12: 42734
B15: 병 력 사 항
E16: 기 간 | G16: 2003-2005 | N16: 최종 계급 | Q16: 병장
E17: 군 별 | G17: 육군 | N17: 병 과
B18: 학 력 | E18: 기 간 | I18: 학교 및 전공 | N18: 졸업년월 | Q18: 최종학력
E19: 2001-03~2003-02 | I19: 동국대 전산원 | L19: 인터넷정보 | N19: 2003.02 | Q19: 초대졸
B23: 경 력 | E23: 재 직 기 간 | K23: 근 무 부 서 | N23: 직 장 명 | P23: 직 위 | R23: 근 무 년 수
E24: 39601 | H24: 43021 | K24: 물류팀 | N24: 날개물류 | R24: =(H24-E24)/365 -> 9.369863
R25: =(H25-E25)/365 -> 0
R26: =(H26-E26)/365 -> 0
P29: 경력합계 | R29: =SUM(R24:T28) -> 9.369863
B30: 가 족 사 항 | E30: 성 명 | H30: 관 계 | J30: 생년월일 | M30: 직 업 | P30: 학력 | S30: 비고
E31: 최대우 | H31: 부 | J31: 18973
E32: 이현주 | H32: 모 | J32: 19933
E33: 김희연 | H33: 배우자 | J33: 30343

Sheet 허철우
B1: 직원 인사 기록 카드
B2: =TODAY() -> 46113
B3: 입 사 일 자 | E3: 43087 | L3: 퇴 사 일 자 | W3: 소속본부 및 팀 | AA3: 연구소 | AE3: IT디자인팀
B5: 이 름 | E5: 허철우 | L5: 종 교 | R5: 사 진
B6: 생 년 월 일 | E6: 33183 | L6: 나 이 | N6: =DATEDIF(E6,TODAY(),"y") -> 35
B7: 주민등록번호 | E7: 901106-1169514 | L7: 근속연수 | N7: =(B2-E3)/365 -> 8.290411
B8: 현 주 소 | E8: 경기도 성남시 | K8: 중원구 금광동 3351번지 4층
B9: 거 주 지 | E9: 경기도 성남시 중원구 금광동 3351번지 4층
B10: 전 화 번 호 | E10: 010-5749-1511 | M10: 결혼유무
B11: 자 격 사 항 | E11: 종 류 | J11: 취 득 일 | O11: 특 기
B15: 병 력 사 항
E16: 기 간 | N16: 최종 계급
E17: 군 별 | N17: 병 과
B18: 학 력 | E18: 기 간 | I18: 학교 및 전공 | N18: 졸업년월 | Q18: 최종학력
E19: 42419 | I19: 한국교통대학교 | L19: 전자공학과 | N19: 2016.02 | Q19: 대졸
I20: 성남서고등학교
B23: 경 력 | E23: 재 직 기 간 | K23: 근 무 부 서 | N23: 직 장 명 | P23: 직 위 | R23: 근 무 년 수
E24: 42401 | H24: 43009 | K24: 조판 | N24: 올댓에디팅 | P24: 사원 | R24: =(H24-E24)/365 -> 1.6657534
E25: 43009 | H25: 43070 | K25: 포토샵 | N25: 메이크원 | P25: 사원 | R25: =(H25-E25)/365 -> 0.16712329
R26: =(H26-E26)/365 -> 0
P29: 경력합계 | R29: =SUM(R24:T28) -> 1.8328767
B30: 가 족 사 항 | E30: 성 명 | H30: 관 계 | J30: 생년월일 | M30: 직 업 | P30: 학력 | S30: 비고
E31: 허용회 | H31: 부 | J31: 22133
E32: 김형숙 | H32: 모 | J32: 23226
E33: 허자람 | H33: 형제 | J33: 32466

Sheet 장호경
B1: 직원 인사 기록 카드
B2: =TODAY() -> 46113
B3: 입 사 일 자 | E3: 43535 | L3: 퇴 사 일 자 | W3: 소속본부 및 팀 | AA3: 연구소 | AE3: 스마트학습팀
B5: 이 름 | E5: 장호경 | L5: 종 교 | R5: 사 진
B6: 생 년 월 일 | E6: 32641 | L6: 나 이 | N6: =DATEDIF(E6,TODAY(),"y") -> 36
B7: 주민등록번호 | E7: 890513-1018825 | L7: 근속연수 | N7: =(B2-E3)/365 -> 7.0630137
B8: 현 주 소 | E8: 인천광역시 서구 | K8: 승학로 495번길 7 101-1803호
B9: 거 주 지 | E9: 서울 은평구 통이로71가길 10-11 202호
B10: 전 화 번 호 | E10: 010-2620-5532 | M10: 결혼유무
B11: 자 격 사 항 | E11: 종 류 | J11: 취 득 일 | O11: 특 기
B15: 병 력 사 항
E16: 기 간 | N16: 최종 계급
E17: 군 별 | N17: 병 과
B18: 학 력 | E18: 기 간 | I18: 학교 및 전공 | N18: 졸업년월 | Q18: 최종학력
E19: 2008.03~2015.02 | I19: 국민대학교 | L19: 수학과 | N19: 2015.02 | Q19: 석사
E20: 2015.03~2017.08 | I20: 성균관대학교 대학원 | L20: 수학교육 | N20: 2017.08
B23: 경 력 | E23: 재 직 기 간 | K23: 근 무 부 서 | N23: 직 장 명 | P23: 직 위 | R23: 근 무 년 수
E24: 42186 | H24: 42401 | K24: 수학부 | N24: 정스터디학원 | R24: =(H24-E24)/365 -> 0.5890411
R25: =(H25-E25)/365 -> 0
R26: =(H26-E26)/365 -> 0
P29: 경력합계 | R29: =SUM(R24:T28) -> 0.5890411
B30: 가 족 사 항 | E30: 성 명 | H30: 관 계 | J30: 생년월일 | M30: 직 업 | P30: 학력 | S30: 비고
E31: 장석기 | H31: 부 | J31: 21287
E32: 박오순 | H32: 모 | J32: 23116
E33: 고설아 | H33: 배우자 | J33: 33560

Sheet 김현종
B1: 직원 인사 기록 카드
B2: =TODAY() -> 46113
B3: 입 사 일 자 | E3: 43983 | L3: 퇴 사 일 자 | W3: 소속본부 및 팀 | AA3: 연구소 | AE3: IT디자인팀
B5: 이 름 | E5: 김현종 | L5: 종 교 | R5: 사 진
B6: 생 년 월 일 | E6: 33519 | L6: 나 이 | N6: =DATEDIF(E6,TODAY(),"y") -> 34
B7: 주민등록번호 | E7: 911008-1046610 | L7: 근속연수 | N7: =(B2-E3)/365 -> 5.8356164
B8: 현 주 소 | E8: 서울특별시 마포구 | K8: 만리재로6길 3-24
B9: 거 주 지 | E9: 서울특별시 마포구 만리재로6길 3-24
B10: 전 화 번 호 | E10: 010-4550-4839 | M10: 결혼유무
B11: 자 격 사 항 | E11: 종 류 | J11: 취 득 일 | O11: 특 기
B15: 병 력 사 항
E16: 기 간 | G16: 2011.04.25~2013.04.24 | N16: 최종 계급 | Q16: 병장
E17: 군 별 | G17: 공군 | N17: 병 과 | Q17: 40110
B18: 학 력 | E18: 기 간 | I18: 학교 및 전공 | N18: 졸업년월 | Q18: 최종학력
E19: 2010.03~2018.02 | I19: 카톨릭대학교 | L19: 정보통신전자공학 | N19: 2018.02 | Q19: 대졸
E20: 2007.03~2010.02 | I20: 배문고등학교
B23: 경 력 | E23: 재 직 기 간 | K23: 근 무 부 서 | N23: 직 장 명 | P23: 직 위 | R23: 근 무 년 수
R24: =(H24-E24)/365 -> 0
R25: =(H25-E25)/365 -> 0
R26: =(H26-E26)/365 -> 0
P29: 경력합계 | R29: =SUM(R24:T28) -> 0
B30: 가 족 사 항 | E30: 성 명 | H30: 관 계 | J30: 생년월일 | M30: 직 업 | P30: 학력 | S30: 비고

Sheet 구자홍
B1: 직원 인사 기록 카드
B2: =TODAY() -> 46113
B3: 입 사 일 자 | E3: 44536 | L3: 퇴 사 일 자 | W3: 소속본부 및 팀 | AA3: 연구소 | AE3: 스마트학습
B5: 이 름 | E5: 구자홍 | L5: 종 교 | R5: 사 진
B6: 생 년 월 일 | E6: 31836 | L6: 나 이 | N6: =DATEDIF(E6,TODAY(),"y") -> 39
B7: 주민등록번호 | E7: 870228-1082425 | L7: 근속연수 | N7: =(B2-E3)/365 -> 4.3205479
B8: 현 주 소 | E8: 서울특별시 강동구 | K8: 아리수로93가길 110, 403-1401호
B9: 거 주 지 | E9: 서울특별시 강동구 아리수로93가길 110, 403-1401호
B10: 전 화 번 호 | E10: 010-7274-9932 | M10: 결혼유무
B11: 자 격 사 항 | E11: 종 류 | J11: 취 득 일 | O11: 특 기
B15: 병 력 사 항
E16: 기 간 | N16: 최종 계급
E17: 군 별 | N17: 병 과
B18: 학 력 | E18: 기 간 | I18: 학교 및 전공 | N18: 졸업년월 | Q18: 최종학력
E19: 2015.03~2017.02 | I19: 성균관대학교 | L19: 수학교육 | N19: 2017.07 | Q19: 석사
I20: 수원대학교 | L20: 수학과
B23: 경 력 | E23: 재 직 기 간 | K23: 근 무 부 서 | N23: 직 장 명 | P23: 직 위 | R23: 근 무 년 수
E24: 43770 | H24: 44531 | K24: 콘텐츠개발 | N24: 비트루브 | P24: 대리 | R24: =(H24-E24)/365 -> 2.0849315
E25: 42705 | H25: 43777 | K25: 강사 | N25: 페르마 | R25: =(H25-E25)/365 -> 2.9369863
R26: =(H26-E26)/365 -> 0
P29: 경력합계 | R29: =SUM(R24:T28) -> 5.0219178
B30: 가 족 사 항 | E30: 성 명 | H30: 관 계 | J30: 생년월일 | M30: 직 업 | P30: 학력 | S30: 비고
E31: 유예지 | H31: 배우자 | J31: 33540

Sheet 지성구
B1: 직원 인사 기록 카드
B2: =TODAY() -> 46113
B3: 입 사 일 자 | E3: 44781 | L3: 퇴 사 일 자 | W3: 소속본부 및 팀 | AA3: 경영총괄실 | AE3: 물류팀
B5: 이 름 | E5: 지성구 | L5: 종 교 | R5: 사 진
B6: 생 년 월 일 | E6: 28354 | L6: 나 이 | N6: =DATEDIF(E6,TODAY(),"y") -> 48
B7: 주민등록번호 | E7: 770817-1079521 | L7: 근속연수 | N7: =(B2-E3)/365 -> 3.6493151
B8: 현 주 소 | E8: 경기도 고양시 일산동구 | K8: 월드고양로 19, 205-4202호
B9: 거 주 지 | E9: 경기도 고양시 일산동구 월드고양로 19, 205-4202호
B10: 전 화 번 호 | E10: 010-6613-3079 | M10: 결혼유무
B11: 자 격 사 항 | E11: 종 류 | J11: 취 득 일 | O11: 특 기
E12: 건설기계조종사 | J12: 2022.7.12
B15: 병 력 사 항
E16: 기 간 | N16: 최종 계급
E17: 군 별 | N17: 병 과
B18: 학 력 | E18: 기 간 | I18: 학교 및 전공 | N18: 졸업년월 | Q18: 최종학력
E19: 1997.03~2003.02 | I19: 가천대학교 | L19: 체육전문학 | N19: 2003.02 | Q19: 대졸
B23: 경 력 | E23: 재 직 기 간 | K23: 근 무 부 서 | N23: 직 장 명 | P23: 직 위 | R23: 근 무 년 수
E24: 39508 | H24: 44682 | K24: 물류 | N24: 팬시로비 | P24: 부장 | R24: =(H24-E24)/365 -> 14.175342
E25: 39083 | H25: 39479 | K25: 물류 | N25: 헤이런제이 | P25: 주임 | R25: =(H25-E25)/365 -> 1.0849315
E26: 38353 | H26: 38838 | K26: 무역부 | N26: 카피어랜드 | P26: 주임 | R26: =(H26-E26)/365 -> 1.3287671
P29: 경력합계 | R29: =SUM(R24:T28) -> 16.589041
B30: 가 족 사 항 | E30: 성 명 | H30: 관 계 | J30: 생년월일 | M30: 직 업 | P30: 학력 | S30: 비고
E31: 최은주 | H31: 배우자 | J31: 28540
E32: 지서진 | H32: 자녀 | J32: 39474
E33: 지예진 | H33: 자녀 | J33: 40645

Sheet 손주호
B1: 직원 인사 기록 카드
B2: =TODAY() -> 46113
B3: 입 사 일 자 | E3: 44984 | L3: 퇴 사 일 자 | W3: 소속본부 및 팀 | AA3: 학원사업본부 | AE3: 가맹사업팀
B5: 이 름 | E5: 손주호 | L5: 종 교 | R5: 사 진
B6: 생 년 월 일 | E6: 32585 | L6: 나 이 | N6: =DATEDIF(E6,TODAY(),"y") -> 37
B7: 주민등록번호 | E7: 890318-1852922 | L7: 근속연수 | N7: =(B2-E3)/365 -> 3.0931507
B8: 현 주 소 | E8: 서울시 동작구 | K8: 여의대방로 24라길 7 401호
B9: 거 주 지 | E9: 서울 동작구 여의대방로 24라길 7 401호
B10: 전 화 번 호 | E10: 010-3793-0468 | M10: 결혼유무
B11: 자 격 사 항 | E11: 종 류 | J11: 취 득 일 | O11: 특 기
B15: 병 력 사 항
E16: 기 간 | N16: 최종 계급
E17: 군 별 | N17: 병 과
B18: 학 력 | E18: 기 간 | I18: 학교 및 전공 | N18: 졸업년월 | Q18: 최종학력
E19: 2008-03 ~ 2016-02 | I19: 대구대학교 | L19: 생명공학과 | N19: 2016.02 | Q19: 대졸
B23: 경 력 | E23: 재 직 기 간 | K23: 근 무 부 서 | N23: 직 장 명 | P23: 직 위 | R23: 근 무 년 수
E24: 43339 | H24: 44925 | K24: 부산사하 본원 | N24: CMS | P24: 대리 | R24: =(H24-E24)/365 -> 4.3452055
R25: =(H25-E25)/365 -> 0
R26: =(H26-E26)/365 -> 0
P29: 경력합계 | R29: =SUM(R24:T28) -> 4.3452055
B30: 가 족 사 항 | E30: 성 명 | H30: 관 계 | J30: 생년월일 | M30: 직 업 | P30: 학력 | S30: 비고
E31: 차본안 | H31: 모 | S31: 010-3687-5699

Sheet 김연경
B1: 직원 인사 기록 카드
B2: =TODAY() -> 46113
B3: 입 사 일 자 | E3: 44984 | L3: 퇴 사 일 자 | W3: 소속본부 및 팀 | AA3: 연구소 | AE3: IT디자인팀
B5: 이 름 | E5: 김연경 | L5: 종 교 | R5: 사 진
B6: 생 년 월 일 | E6: 35319 | L6: 나 이 | N6: =DATEDIF(E6,TODAY(),"y") -> 29
B7: 주민등록번호 | E7: 960911-2078812 | L7: 근속연수 | N7: =(B2-E3)/365 -> 3.0931507
B8: 현 주 소 | E8: 경기도 하남시 | K8: 감일로 86 103동 2004호
B9: 거 주 지 | E9: 경기도 하남시 감일로 86 103동 2004호
B10: 전 화 번 호 | E10: 010-8612-9596 | M10: 결혼유무
B11: 자 격 사 항 | E11: 종 류 | J11: 취 득 일 | O11: 특 기
E12: 컴퓨터활용능력 2급 | J12: 44666
E13: SNS마케팅전문가 1급 | J13: 44627
E14: 중등학교정교사(중국어) 2급 | J14: 43699
E15: 독서지도사 2급 | J15: 43677
E16: 한국사능력검정시험 3급 | J16: 43777
B17: 병 력 사 항
E18: 기 간 | N18: 최종 계급
E19: 군 별 | N19: 병 과
B20: 학 력 | E20: 기 간 | I20: 학교 및 전공 | N20: 졸업년월 | Q20: 최종학력
E21: 2016-03 ~ 2019-08 | I21: 배재대학교 | L21: 중국학과 | N21: 2016.02 | Q21: 대졸
B25: 경 력 | E25: 재 직 기 간 | K25: 근 무 부 서 | N25: 직 장 명 | P25: 직 위 | R25: 근 무 년 수
E26: 44707 | H26: 44799 | K26: BM | N26: 스포메틱스 | R26: =(H26-E26)/365 -> 0.25205479
E27: 44445 | H27: 44620 | K27: 마케팅/학습관리/원생관리 | N27: EIE고려대어학원 | R27: =(H27-E27)/365 -> 0.47945205
E28: 44428 | H28: 44620 | K28: 중국어강사 | N28: 행당중학교 | R28: =(H28-E28)/365 -> 0.5260274
P31: 경력합계 | R31: =SUM(R26:T30) -> 1.2575342
B32: 가 족 사 항 | E32: 성 명 | H32: 관 계 | J32: 생년월일 | M32: 직 업 | P32: 학력 | S32: 비고
E33: 김문수 | H33: 부 | J33: 23002 | S33: 010-9031-0167
E34: 탁현호 | H34: 모 | J34: 26263
E35: 김연진 | H35: 형제 | J35: 34948
E36: 김사론 | H36: 형제 | J36: 39494

Sheet 한정규
B1: 직원 인사 기록 카드
B2: =TODAY() -> 46113
B3: 입 사 일 자 | E3: 45170 | L3: 퇴 사 일 자 | W3: 소속본부 및 팀 | AA3: 신사업본부
B5: 이 름 | E5: 한정규 | L5: 종 교 | R5: 사 진
B6: 생 년 월 일 | E6: 33974 | L6: 나 이 | N6: =DATEDIF(E6,TODAY(),"y") -> 33
B7: 주민등록번호 | E7: 930105-1690925 | L7: 근속연수 | N7: =(B2-E3)/365 -> 2.5835616
B8: 현 주 소 | E8: 서울시 용산구 | K8: 백범로90길 26, 102동 2403호
B9: 거 주 지 | E9: 서울 용산구 백범로90길 26, 102동 2403호
B10: 전 화 번 호 | E10: 010-6474-8886 | M10: 결혼유무
B11: 자 격 사 항 | E11: 종 류 | J11: 취 득 일 | O11: 특 기
B15: 병 력 사 항
E16: 기 간 | N16: 최종 계급
E17: 군 별 | N17: 병 과
B18: 학 력 | E18: 기 간 | I18: 학교 및 전공 | N18: 졸업년월 | Q18: 최종학력
B23: 경 력 | E23: 재 직 기 간 | K23: 근 무 부 서 | N23: 직 장 명 | P23: 직 위 | R23: 근 무 년 수
R24: =(H24-E24)/365 -> 0
R25: =(H25-E25)/365 -> 0
R26: =(H26-E26)/365 -> 0
P29: 경력합계 | R29: =SUM(R24:T28) -> 0
B30: 가 족 사 항 | E30: 성 명 | H30: 관 계 | J30: 생년월일 | M30: 직 업 | P30: 학력 | S30: 비고

Sheet 최정우
B1: 직원 인사 기록 카드
B2: =TODAY() -> 46113
B3: 입 사 일 자 | E3: 45593 | L3: 퇴 사 일 자 | W3: 소속본부 및 팀 | AA3: 경영총괄실 | AE3: 경영지원팀
B5: 이 름 | E5: 최정우 | L5: 종 교 | R5: 사 진
B6: 생 년 월 일 | E6: 34694 | L6: 나 이 | N6: =DATEDIF(E6,TODAY(),"y") -> 31
B7: 주민등록번호 | E7: 941226-1070727 | L7: 근속연수 | N7: =(B2-E3)/365 -> 1.4246575
B8: 현 주 소 | E8: 경기도 광명시 | K8: 시청로 50 111동 602호
B9: 거 주 지 | E9: 경기도 광명시 시청로 50 111동 602호
B10: 전 화 번 호 | E10: 010-3046-4085 | M10: 결혼유무
B11: 자 격 사 항 | E11: 종 류 | J11: 취 득 일 | O11: 특 기
E12: 컴퓨터활용능력1급 | J12: 2020.11
E13: 사회조사분석사2급 | J13: 2019.11
B15: 병 력 사 항
E16: 기 간 | G16: 2018.09~2020.07 | N16: 최종 계급 | Q16: 병장
E17: 군 별 | G17: 공군 | N17: 병 과
B18: 학 력 | E18: 기 간 | I18: 학교 및 전공 | N18: 졸업년월 | Q18: 최종학력
E19: 2015.03~2021.02 | I19: 카톨릭대학교 | L19: 국어국문 | N19: 2021.02 | Q19: 대졸
E20: 2013 졸업 | I20: 광명북고등학교 | L20: 문과 | N20: 2013.02
B23: 경 력 | E23: 재 직 기 간 | K23: 근 무 부 서 | N23: 직 장 명 | P23: 직 위 | R23: 근 무 년 수
E24: 44501 | H24: 44620 | K24: 방사보건원 | N24: 한수원 | P24: 인턴 | R24: =(H24-E24)/365 -> 0.3260274
E25: 44287 | H25: 44500 | K25: 인재개발원 | N25: 한수원 | P25: 인턴 | R25: =(H25-E25)/365 -> 0.58356164
R26: =(H26-E26)/365 -> 0
P29: 경력합계 | R29: =SUM(R24:T28) -> 0.90958904
B30: 가 족 사 항 | E30: 성 명 | H30: 관 계 | J30: 생년월일 | M30: 직 업 | P30: 학력 | S30: 비고
E31: 최을식 | H31: 부 | J31: 23668
E32: 정미금 | H32: 모 | J32: 24911
E33: 최정윤 | H33: 형제 | J33: 36074

Sheet 이준호
B1: 직원 인사 기록 카드
B2: =TODAY() -> 46113
B3: 입 사 일 자 | E3: 45659 | L3: 퇴 사 일 자 | W3: 소속본부 및 팀 | AA3: 경영총괄실
B5: 이 름 | E5: 이준호 | L5: 종 교 | R5: 사 진
B6: 생 년 월 일 | E6: 33615 | L6: 나 이 | N6: =DATEDIF(E6,TODAY(),"y") -> 34
B7: 주민등록번호 | E7: 920112-1030511 | L7: 근속연수 | N7: =(B2-E3)/365 -> 1.2438356
B8: 현 주 소 | E8: 서울시 중랑구 | K8: 면목동 79길 8-21
B9: 거 주 지 | E9: 서울시 중랑구 면목동 79길 8-21
B10: 전 화 번 호 | E10: 010-7273-1393 | M10: 결혼유무
B11: 자 격 사 항 | E11: 종 류 | J11: 취 득 일 | O11: 특 기
B15: 병 력 사 항
E16: 기 간 | N16: 최종 계급
E17: 군 별 | N17: 병 과
B18: 학 력 | E18: 기 간 | I18: 학교 및 전공 | N18: 졸업년월 | Q18: 최종학력
E19: 2009 ~2011 | I19: Northwest Missouri State University | L19: Mathmatics & science | N19: 2011 | Q19: 대졸
E20: 2011-2015 | I20: Boston University | L20: chemistry | N20: 2015
B23: 경 력 | E23: 재 직 기 간 | K23: 근 무 부 서 | N23: 직 장 명 | P23: 직 위 | R23: 근 무 년 수
E24: 42628 | H24: 42845 | K24: 자영업 | N24: 비슈어보컬리스트 | R24: =(H24-E24)/365 -> 0.59452055
E25: 42845 | H25: 43130 | K25: 자영업 | N25: 브이알웨이 | R25: =(H25-E25)/365 -> 0.78082192
R26: =(H26-E26)/365 -> 0
P29: 경력합계 | R29: =SUM(R24:T28) -> 1.3753425
B30: 가 족 사 항 | E30: 성 명 | H30: 관 계 | J30: 생년월일 | M30: 직 업 | P30: 학력 | S30: 비고

Sheet 이영주
B1: 직원 인사 기록 카드
B2: =TODAY() -> 46113
B3: 입 사 일 자 | E3: 45689 | L3: 퇴 사 일 자 | W3: 소속본부 및 팀 | AA3: 연구소 | AE3: 개발팀
B5: 이 름 | E5: 이영주 | L5: 종 교 | R5: 사 진
B6: 생 년 월 일 | E6: 36961 | L6: 나 이 | N6: =DATEDIF(E6,TODAY(),"y") -> 25
B7: 주민등록번호 | E7: 010311-4382111 | L7: 근속연수 | N7: =(B2-E3)/365 -> 1.1616438
B8: 현 주 소 | E8: 서울시 강북구 | K8: 덕릉로 111 9층 904호
B9: 거 주 지 | E9: 서울시 강북구 덕릉로 111 9층 904호
B10: 전 화 번 호 | E10: 010-4515-4384 | M10: 결혼유무
B11: 자 격 사 항 | E11: 종 류 | J11: 취 득 일 | O11: 특 기
E12: 정보처리기사 | J12: 2023.11
E13: 컴퓨터활용능력 1급 | J13: 2022.02
B15: 병 력 사 항
E16: 기 간 | N16: 최종 계급
E17: 군 별 | N17: 병 과
B18: 학 력 | E18: 기 간 | I18: 학교 및 전공 | N18: 졸업년월 | Q18: 최종학력
E19: 2020.03 ~ 2024.02 | I19: 서울여자대학교 | L19: 수학과 | N19: 2024.02 | Q19: 대졸
B23: 경 력 | E23: 재 직 기 간 | K23: 근 무 부 서 | N23: 직 장 명 | P23: 직 위 | R23: 근 무 년 수
R24: =(H24-E24)/365 -> 0
R25: =(H25-E25)/365 -> 0
R26: =(H26-E26)/365 -> 0
P29: 경력합계 | R29: =SUM(R24:T28) -> 0
B30: 가 족 사 항 | E30: 성 명 | H30: 관 계 | J30: 생년월일 | M30: 직 업 | P30: 학력 | S30: 비고

Sheet 진하람
B1: 직원 인사 기록 카드
B2: =TODAY() -> 46113
B3: 입 사 일 자 | E3: 45689 | L3: 퇴 사 일 자 | W3: 소속본부 및 팀 | AA3: 연구소 | AE3: 개발팀
B5: 이 름 | E5: 진하람 | L5: 종 교 | R5: 사 진
B6: 생 년 월 일 | E6: 34049 | L6: 나 이 | N6: =DATEDIF(E6,TODAY(),"y") -> 33
B7: 주민등록번호 | E7: 930321-1284118 | L7: 근속연수 | N7: =(B2-E3)/365 -> 1.1616438
B8: 현 주 소 | E8: 서울시 동대문구 | K8: 사가정로21가길 13-3
B9: 거 주 지 | E9: 서울시 동대문구 사가정로21가길 13-3
B10: 전 화 번 호 | E10: 010-7346-2392 | M10: 결혼유무
B11: 자 격 사 항 | E11: 종 류 | J11: 취 득 일 | O11: 특 기
B15: 병 력 사 항
E16: 기 간 | G16: 2014-05 ~ 2016-02 | N16: 최종 계급 | Q16: 병장
E17: 군 별 | G17: 육군 | N17: 병 과
B18: 학 력 | E18: 기 간 | I18: 학교 및 전공 | N18: 졸업년월 | Q18: 최종학력
E19: 2012.02~2019.02 | I19: 한양대학교 | L19: 수학과 | N19: 2019.02 | Q19: 대졸
B23: 경 력 | E23: 재 직 기 간 | K23: 근 무 부 서 | N23: 직 장 명 | P23: 직 위 | R23: 근 무 년 수
E24: 2023.06 | H24: 2024.05 | N24: (주)올마이티캠퍼스 | P24: 강사 | R24: =(H24-E24)/365 -> 0.0027123288
E25: 2022.01 | H25: 2023.05 | N25: 한수학학원 | P25: 강사 | R25: =(H25-E25)/365 -> 0.0028493151
E26: 2020.03 | H26: 2022.02 | N26: 김지현플러스수학학원 | P26: 강사 | R26: =(H26-E26)/365 -> 0.0054520548
P29: 경력합계 | R29: =SUM(R24:T28) -> 0.011013699
B30: 가 족 사 항 | E30: 성 명 | H30: 관 계 | J30: 생년월일 | M30: 직 업 | P30: 학력 | S30: 비고

Sheet 김태경
B1: 직원 인사 기록 카드
B2: =TODAY() -> 46113
B3: 입 사 일 자 | E3: 45748 | L3: 퇴 사 일 자 | W3: 소속본부 및 팀 | AA3: 경영총괄실 | AE3: 물류팀
B5: 이 름 | E5: 김태경 | L5: 종 교 | R5: 사 진
B6: 생 년 월 일 | E6: 22397 | L6: 나 이 | N6: =DATEDIF(E6,TODAY(),"y") -> 64
B7: 주민등록번호 | E7: 610426-1675423 | L7: 근속연수 | N7: =(B2-E3)/365 -> 1
B8: 현 주 소 | E8: 경기도 파주시 | K8: 용상골길 186-43
B9: 거 주 지 | E9: 상동
B10: 전 화 번 호 | E10: 010-4503-6632 | M10: 결혼유무
B11: 자 격 사 항 | E11: 종 류 | J11: 취 득 일 | O11: 특 기
B15: 병 력 사 항
E16: 기 간 | N16: 최종 계급
E17: 군 별 | N17: 병 과
B18: 학 력 | E18: 기 간 | I18: 학교 및 전공 | N18: 졸업년월 | Q18: 최종학력
B23: 경 력 | E23: 재 직 기 간 | K23: 근 무 부 서 | N23: 직 장 명 | P23: 직 위 | R23: 근 무 년 수
R24: =(H24-E24)/365 -> 0
R25: =(H25-E25)/365 -> 0
R26: =(H26-E26)/365 -> 0
P29: 경력합계 | R29: =SUM(R24:T28) -> 0
B30: 가 족 사 항 | E30: 성 명 | H30: 관 계 | J30: 생년월일 | M30: 직 업 | P30: 학력 | S30: 비고
E31: 김경애 | H31: 처 | J31: 24026

Sheet 황대위_퇴사
B1: 직원 인사 기록 카드
B2: =TODAY() -> 46113
B3: 입 사 일 자 | E3: 45717 | L3: 퇴 사 일 자 | O3: 45869 | W3: 소속본부 및 팀 | AA3: 출판사업본부
B5: 이 름 | E5: 황대위 | L5: 종 교 | R5: 사 진
B6: 생 년 월 일 | E6: 33716 | L6: 나 이 | N6: =DATEDIF(E6,TODAY(),"y") -> 33
B7: 주민등록번호 | E7: 920422-1011811 | L7: 근속연수 | N7: =(B2-E3)/365 -> 1.0849315
B8: 현 주 소 | E8: 서울시 중랑구 묵동 | K8: 묵동 188-1 장미아파트 3-307
B9: 거 주 지 | E9: 서울시 중랑구 묵동 188-1 장미아파트 3-307
B10: 전 화 번 호 | E10: 010-7132-3334 | M10: 결혼유무
B11: 자 격 사 항 | E11: 종 류 | J11: 취 득 일 | O11: 특 기
B15: 병 력 사 항
E16: 기 간 | G16: 면제 | N16: 최종 계급 | Q16: 면제
E17: 군 별 | N17: 병 과
B18: 학 력 | E18: 기 간 | I18: 학교 및 전공 | N18: 졸업년월 | Q18: 최종학력
E19: 2011.03 ~ 2015.02 | I19: 동서울대학 | L19: 정보통신 | N19: 2024.02 | Q19: 대졸
B23: 경 력 | E23: 재 직 기 간 | K23: 근 무 부 서 | N23: 직 장 명 | P23: 직 위 | R23: 근 무 년 수
E24: 2021.12 | H24: 2024.09 | K24: b2b영업 | N24: ㈜에브리플레이 | R24: =(H24-E24)/365 -> 0.0081369863
E25: 2020.07 | H25: 2021.1 | K25: 법인영업 | N25: ㈜에스티엠넷 | R25: =(H25-E25)/365 -> 0.0028219178
E26: 2018.08 | H26: 2019.02 | K26: 동부지점 | N26: ㈜골든블루 | R26: =(H26-E26)/365 -> 0.0025753425
E27: 2017.09 | H27: 2018.08 | K27: 유흥판촉 | N27: ㈜롯데아사히주류
P29: 경력합계 | R29: =SUM(R24:T28) -> 0.013534247
B30: 가 족 사 항 | E30: 성 명 | H30: 관 계 | J30: 생년월일 | M30: 직 업 | P30: 학력 | S30: 비고

Sheet 조성아_퇴사
B1: 직원 인사 기록 카드
B2: =TODAY() -> 46113
B3: 입 사 일 자 | E3: 43155 | L3: 퇴 사 일 자 | O3: 45620 | W3: 소속본부 및 팀 | AA3: 학원사업본부 | AE3: 직영관리팀
B5: 이 름 | E5: 조 성 아 | L5: 종 교 | R5: 사 진
B6: 생 년 월 일 | E6: 33198 | L6: 나 이 | N6: =DATEDIF(E6,TODAY(),"y") -> 35
